2018-01-24 22:16:29,473 base.py [django.request:256] [ERROR]- Internal Server Error: /
Traceback (most recent call last):
  File "J:\arno\pythonenv\lib\site-packages\django\core\handlers\base.py", line 119, in get_response
    resolver_match = resolver.resolve(request.path_info)
  File "J:\arno\pythonenv\lib\site-packages\django\core\urlresolvers.py", line 366, in resolve
    for pattern in self.url_patterns:
  File "J:\arno\pythonenv\lib\site-packages\django\core\urlresolvers.py", line 402, in url_patterns
    patterns = getattr(self.urlconf_module, "urlpatterns", self.urlconf_module)
  File "J:\arno\pythonenv\lib\site-packages\django\core\urlresolvers.py", line 396, in urlconf_module
    self._urlconf_module = import_module(self.urlconf_name)
  File "c:\python27\Lib\importlib\__init__.py", line 37, in import_module
    __import__(name)
  File "J:\arno\pythonenv\phx_web\phxweb\urls.py", line 13, in <module>
    url(r'^static/(?P<path>.*)$', 'django.views.static.serve', {'document_root': settings.STATIC_ROOT}),
NameError: name 'settings' is not defined
2018-01-24 22:16:30,967 base.py [django.request:256] [ERROR]- Internal Server Error: /
Traceback (most recent call last):
  File "J:\arno\pythonenv\lib\site-packages\django\core\handlers\base.py", line 119, in get_response
    resolver_match = resolver.resolve(request.path_info)
  File "J:\arno\pythonenv\lib\site-packages\django\core\urlresolvers.py", line 366, in resolve
    for pattern in self.url_patterns:
  File "J:\arno\pythonenv\lib\site-packages\django\core\urlresolvers.py", line 402, in url_patterns
    patterns = getattr(self.urlconf_module, "urlpatterns", self.urlconf_module)
  File "J:\arno\pythonenv\lib\site-packages\django\core\urlresolvers.py", line 396, in urlconf_module
    self._urlconf_module = import_module(self.urlconf_name)
  File "c:\python27\Lib\importlib\__init__.py", line 37, in import_module
    __import__(name)
  File "J:\arno\pythonenv\phx_web\phxweb\urls.py", line 13, in <module>
    url(r'^static/(?P<path>.*)$', 'django.views.static.serve', {'document_root': settings.STATIC_ROOT}),
NameError: name 'settings' is not defined
2018-01-24 23:11:14,657 base.py [django.request:256] [ERROR]- Internal Server Error: /admin
Traceback (most recent call last):
  File "J:\arno\pythonenv\lib\site-packages\django\core\handlers\base.py", line 108, in get_response
    response = middleware_method(request)
  File "J:\arno\pythonenv\lib\site-packages\django\middleware\common.py", line 74, in process_request
    if (not urlresolvers.is_valid_path(request.path_info, urlconf) and
  File "J:\arno\pythonenv\lib\site-packages\django\core\urlresolvers.py", line 647, in is_valid_path
    resolve(path, urlconf)
  File "J:\arno\pythonenv\lib\site-packages\django\core\urlresolvers.py", line 522, in resolve
    return get_resolver(urlconf).resolve(path)
  File "J:\arno\pythonenv\lib\site-packages\django\core\urlresolvers.py", line 366, in resolve
    for pattern in self.url_patterns:
  File "J:\arno\pythonenv\lib\site-packages\django\core\urlresolvers.py", line 402, in url_patterns
    patterns = getattr(self.urlconf_module, "urlpatterns", self.urlconf_module)
  File "J:\arno\pythonenv\lib\site-packages\django\core\urlresolvers.py", line 396, in urlconf_module
    self._urlconf_module = import_module(self.urlconf_name)
  File "c:\python27\Lib\importlib\__init__.py", line 37, in import_module
    __import__(name)
  File "J:\arno\pythonenv\phx_web\phxweb\urls.py", line 16, in <module>
    url(r'^', include('monitor.urls')),
  File "J:\arno\pythonenv\lib\site-packages\django\conf\urls\__init__.py", line 33, in include
    urlconf_module = import_module(urlconf_module)
  File "c:\python27\Lib\importlib\__init__.py", line 37, in import_module
    __import__(name)
  File "J:\arno\pythonenv\phx_web\monitor\urls.py", line 3, in <module>
    from . import views
  File "J:\arno\pythonenv\phx_web\monitor\views.py", line 13
SyntaxError: Non-ASCII character '\xe7' in file J:\arno\pythonenv\phx_web\monitor\views.py on line 13, but no encoding declared; see http://python.org/dev/peps/pep-0263/ for details
2018-01-24 23:11:14,861 base.py [django.request:256] [ERROR]- Internal Server Error: /favicon.ico
Traceback (most recent call last):
  File "J:\arno\pythonenv\lib\site-packages\django\core\handlers\base.py", line 108, in get_response
    response = middleware_method(request)
  File "J:\arno\pythonenv\lib\site-packages\django\middleware\common.py", line 74, in process_request
    if (not urlresolvers.is_valid_path(request.path_info, urlconf) and
  File "J:\arno\pythonenv\lib\site-packages\django\core\urlresolvers.py", line 647, in is_valid_path
    resolve(path, urlconf)
  File "J:\arno\pythonenv\lib\site-packages\django\core\urlresolvers.py", line 522, in resolve
    return get_resolver(urlconf).resolve(path)
  File "J:\arno\pythonenv\lib\site-packages\django\core\urlresolvers.py", line 366, in resolve
    for pattern in self.url_patterns:
  File "J:\arno\pythonenv\lib\site-packages\django\core\urlresolvers.py", line 402, in url_patterns
    patterns = getattr(self.urlconf_module, "urlpatterns", self.urlconf_module)
  File "J:\arno\pythonenv\lib\site-packages\django\core\urlresolvers.py", line 396, in urlconf_module
    self._urlconf_module = import_module(self.urlconf_name)
  File "c:\python27\Lib\importlib\__init__.py", line 37, in import_module
    __import__(name)
  File "J:\arno\pythonenv\phx_web\phxweb\urls.py", line 16, in <module>
    url(r'^', include('monitor.urls')),
  File "J:\arno\pythonenv\lib\site-packages\django\conf\urls\__init__.py", line 33, in include
    urlconf_module = import_module(urlconf_module)
  File "c:\python27\Lib\importlib\__init__.py", line 37, in import_module
    __import__(name)
  File "J:\arno\pythonenv\phx_web\monitor\urls.py", line 3, in <module>
    from . import views
  File "J:\arno\pythonenv\phx_web\monitor\views.py", line 13
SyntaxError: Non-ASCII character '\xe7' in file J:\arno\pythonenv\phx_web\monitor\views.py on line 13, but no encoding declared; see http://python.org/dev/peps/pep-0263/ for details
2018-01-24 23:11:17,888 base.py [django.request:256] [ERROR]- Internal Server Error: /admin/
Traceback (most recent call last):
  File "J:\arno\pythonenv\lib\site-packages\django\core\handlers\base.py", line 119, in get_response
    resolver_match = resolver.resolve(request.path_info)
  File "J:\arno\pythonenv\lib\site-packages\django\core\urlresolvers.py", line 366, in resolve
    for pattern in self.url_patterns:
  File "J:\arno\pythonenv\lib\site-packages\django\core\urlresolvers.py", line 402, in url_patterns
    patterns = getattr(self.urlconf_module, "urlpatterns", self.urlconf_module)
  File "J:\arno\pythonenv\lib\site-packages\django\core\urlresolvers.py", line 396, in urlconf_module
    self._urlconf_module = import_module(self.urlconf_name)
  File "c:\python27\Lib\importlib\__init__.py", line 37, in import_module
    __import__(name)
  File "J:\arno\pythonenv\phx_web\phxweb\urls.py", line 16, in <module>
    url(r'^', include('monitor.urls')),
  File "J:\arno\pythonenv\lib\site-packages\django\conf\urls\__init__.py", line 33, in include
    urlconf_module = import_module(urlconf_module)
  File "c:\python27\Lib\importlib\__init__.py", line 37, in import_module
    __import__(name)
  File "J:\arno\pythonenv\phx_web\monitor\urls.py", line 3, in <module>
    from . import views
  File "J:\arno\pythonenv\phx_web\monitor\views.py", line 13
SyntaxError: Non-ASCII character '\xe7' in file J:\arno\pythonenv\phx_web\monitor\views.py on line 13, but no encoding declared; see http://python.org/dev/peps/pep-0263/ for details
2018-01-24 23:11:18,035 base.py [django.request:256] [ERROR]- Internal Server Error: /favicon.ico
Traceback (most recent call last):
  File "J:\arno\pythonenv\lib\site-packages\django\core\handlers\base.py", line 108, in get_response
    response = middleware_method(request)
  File "J:\arno\pythonenv\lib\site-packages\django\middleware\common.py", line 74, in process_request
    if (not urlresolvers.is_valid_path(request.path_info, urlconf) and
  File "J:\arno\pythonenv\lib\site-packages\django\core\urlresolvers.py", line 647, in is_valid_path
    resolve(path, urlconf)
  File "J:\arno\pythonenv\lib\site-packages\django\core\urlresolvers.py", line 522, in resolve
    return get_resolver(urlconf).resolve(path)
  File "J:\arno\pythonenv\lib\site-packages\django\core\urlresolvers.py", line 366, in resolve
    for pattern in self.url_patterns:
  File "J:\arno\pythonenv\lib\site-packages\django\core\urlresolvers.py", line 402, in url_patterns
    patterns = getattr(self.urlconf_module, "urlpatterns", self.urlconf_module)
  File "J:\arno\pythonenv\lib\site-packages\django\core\urlresolvers.py", line 396, in urlconf_module
    self._urlconf_module = import_module(self.urlconf_name)
  File "c:\python27\Lib\importlib\__init__.py", line 37, in import_module
    __import__(name)
  File "J:\arno\pythonenv\phx_web\phxweb\urls.py", line 16, in <module>
    url(r'^', include('monitor.urls')),
  File "J:\arno\pythonenv\lib\site-packages\django\conf\urls\__init__.py", line 33, in include
    urlconf_module = import_module(urlconf_module)
  File "c:\python27\Lib\importlib\__init__.py", line 37, in import_module
    __import__(name)
  File "J:\arno\pythonenv\phx_web\monitor\urls.py", line 3, in <module>
    from . import views
  File "J:\arno\pythonenv\phx_web\monitor\views.py", line 13
SyntaxError: Non-ASCII character '\xe7' in file J:\arno\pythonenv\phx_web\monitor\views.py on line 13, but no encoding declared; see http://python.org/dev/peps/pep-0263/ for details
2018-01-24 23:41:12,190 base.py [django.request:256] [ERROR]- Internal Server Error: /
Traceback (most recent call last):
  File "J:\arno\pythonenv\lib\site-packages\django\core\handlers\base.py", line 132, in get_response
    response = wrapped_callback(request, *callback_args, **callback_kwargs)
  File "J:\arno\pythonenv\lib\site-packages\django\utils\decorators.py", line 110, in _wrapped_view
    response = view_func(request, *args, **kwargs)
  File "J:\arno\pythonenv\lib\site-packages\django\contrib\auth\decorators.py", line 22, in _wrapped_view
    return view_func(request, *args, **kwargs)
  File "J:\arno\pythonenv\phx_web\monitor\views.py", line 30, in index
    'username': username,
  File "J:\arno\pythonenv\lib\site-packages\django\shortcuts.py", line 67, in render
    template_name, context, request=request, using=using)
  File "J:\arno\pythonenv\lib\site-packages\django\template\loader.py", line 99, in render_to_string
    return template.render(context, request)
  File "J:\arno\pythonenv\lib\site-packages\django\template\backends\django.py", line 74, in render
    return self.template.render(context)
  File "J:\arno\pythonenv\lib\site-packages\django\template\base.py", line 209, in render
    return self._render(context)
  File "J:\arno\pythonenv\lib\site-packages\django\template\base.py", line 201, in _render
    return self.nodelist.render(context)
  File "J:\arno\pythonenv\lib\site-packages\django\template\base.py", line 903, in render
    bit = self.render_node(node, context)
  File "J:\arno\pythonenv\lib\site-packages\django\template\debug.py", line 79, in render_node
    return node.render(context)
  File "J:\arno\pythonenv\lib\site-packages\django\template\loader_tags.py", line 151, in render
    template = context.template.engine.get_template(template)
  File "J:\arno\pythonenv\lib\site-packages\django\template\engine.py", line 167, in get_template
    template, origin = self.find_template(template_name, dirs)
  File "J:\arno\pythonenv\lib\site-packages\django\template\engine.py", line 141, in find_template
    source, display_name = loader(name, dirs)
  File "J:\arno\pythonenv\lib\site-packages\django\template\loaders\base.py", line 13, in __call__
    return self.load_template(template_name, template_dirs)
  File "J:\arno\pythonenv\lib\site-packages\django\template\loaders\base.py", line 23, in load_template
    template = Template(source, origin, template_name, self.engine)
  File "J:\arno\pythonenv\lib\site-packages\django\template\base.py", line 190, in __init__
    self.nodelist = engine.compile_string(template_string, origin)
  File "J:\arno\pythonenv\lib\site-packages\django\template\engine.py", line 261, in compile_string
    return parser.parse()
  File "J:\arno\pythonenv\lib\site-packages\django\template\base.py", line 341, in parse
    compiled_result = compile_func(self, token)
  File "J:\arno\pythonenv\lib\site-packages\django\template\defaulttags.py", line 1010, in do_if
    nodelist = parser.parse(('elif', 'else', 'endif'))
  File "J:\arno\pythonenv\lib\site-packages\django\template\base.py", line 339, in parse
    self.invalid_block_tag(token, command, parse_until)
  File "J:\arno\pythonenv\lib\site-packages\django\template\base.py", line 394, in invalid_block_tag
    (command, get_text_list(["'%s'" % p for p in parse_until])))
TemplateSyntaxError: Invalid block tag: 'endcomment', expected 'elif', 'else' or 'endif'
2018-01-24 23:47:44,305 base.py [django.request:256] [ERROR]- Internal Server Error: /
Traceback (most recent call last):
  File "J:\arno\pythonenv\lib\site-packages\django\core\handlers\base.py", line 119, in get_response
    resolver_match = resolver.resolve(request.path_info)
  File "J:\arno\pythonenv\lib\site-packages\django\core\urlresolvers.py", line 366, in resolve
    for pattern in self.url_patterns:
  File "J:\arno\pythonenv\lib\site-packages\django\core\urlresolvers.py", line 402, in url_patterns
    patterns = getattr(self.urlconf_module, "urlpatterns", self.urlconf_module)
  File "J:\arno\pythonenv\lib\site-packages\django\core\urlresolvers.py", line 396, in urlconf_module
    self._urlconf_module = import_module(self.urlconf_name)
  File "c:\python27\Lib\importlib\__init__.py", line 37, in import_module
    __import__(name)
  File "J:\arno\pythonenv\phx_web\phxweb\urls.py", line 17, in <module>
    url(r'^', include('monitor.urls')),
  File "J:\arno\pythonenv\lib\site-packages\django\conf\urls\__init__.py", line 33, in include
    urlconf_module = import_module(urlconf_module)
  File "c:\python27\Lib\importlib\__init__.py", line 37, in import_module
    __import__(name)
  File "J:\arno\pythonenv\phx_web\monitor\urls.py", line 7, in <module>
    url('^services$', views.services, name='services'),
AttributeError: 'module' object has no attribute 'services'
2018-01-24 23:50:20,507 base.py [django.request:256] [ERROR]- Internal Server Error: /monitor/services
Traceback (most recent call last):
  File "J:\arno\pythonenv\lib\site-packages\django\core\handlers\base.py", line 132, in get_response
    response = wrapped_callback(request, *callback_args, **callback_kwargs)
  File "J:\arno\pythonenv\lib\site-packages\django\utils\decorators.py", line 110, in _wrapped_view
    response = view_func(request, *args, **kwargs)
  File "J:\arno\pythonenv\lib\site-packages\django\contrib\auth\decorators.py", line 22, in _wrapped_view
    return view_func(request, *args, **kwargs)
  File "J:\arno\pythonenv\phx_web\monitor\views.py", line 48, in services
    LimitAccess(role, 'monitor/monitor_index.html'),
NameError: global name 'LimitAccess' is not defined
2018-01-27 14:58:08,927 base.py [django.request:256] [ERROR]- Internal Server Error: /admin/monitor/project_t/
Traceback (most recent call last):
  File "J:\arno\pythonenv\lib\site-packages\django\core\handlers\base.py", line 164, in get_response
    response = response.render()
  File "J:\arno\pythonenv\lib\site-packages\django\template\response.py", line 158, in render
    self.content = self.rendered_content
  File "J:\arno\pythonenv\lib\site-packages\django\template\response.py", line 135, in rendered_content
    content = template.render(context, self._request)
  File "J:\arno\pythonenv\lib\site-packages\django\template\backends\django.py", line 74, in render
    return self.template.render(context)
  File "J:\arno\pythonenv\lib\site-packages\django\template\base.py", line 209, in render
    return self._render(context)
  File "J:\arno\pythonenv\lib\site-packages\django\template\base.py", line 201, in _render
    return self.nodelist.render(context)
  File "J:\arno\pythonenv\lib\site-packages\django\template\base.py", line 903, in render
    bit = self.render_node(node, context)
  File "J:\arno\pythonenv\lib\site-packages\django\template\debug.py", line 79, in render_node
    return node.render(context)
  File "J:\arno\pythonenv\lib\site-packages\django\template\loader_tags.py", line 135, in render
    return compiled_parent._render(context)
  File "J:\arno\pythonenv\lib\site-packages\django\template\base.py", line 201, in _render
    return self.nodelist.render(context)
  File "J:\arno\pythonenv\lib\site-packages\django\template\base.py", line 903, in render
    bit = self.render_node(node, context)
  File "J:\arno\pythonenv\lib\site-packages\django\template\debug.py", line 79, in render_node
    return node.render(context)
  File "J:\arno\pythonenv\lib\site-packages\django\template\loader_tags.py", line 135, in render
    return compiled_parent._render(context)
  File "J:\arno\pythonenv\lib\site-packages\django\template\base.py", line 201, in _render
    return self.nodelist.render(context)
  File "J:\arno\pythonenv\lib\site-packages\django\template\base.py", line 903, in render
    bit = self.render_node(node, context)
  File "J:\arno\pythonenv\lib\site-packages\django\template\debug.py", line 79, in render_node
    return node.render(context)
  File "J:\arno\pythonenv\lib\site-packages\django\template\loader_tags.py", line 65, in render
    result = block.nodelist.render(context)
  File "J:\arno\pythonenv\lib\site-packages\django\template\base.py", line 903, in render
    bit = self.render_node(node, context)
  File "J:\arno\pythonenv\lib\site-packages\django\template\debug.py", line 79, in render_node
    return node.render(context)
  File "J:\arno\pythonenv\lib\site-packages\django\template\loader_tags.py", line 65, in render
    result = block.nodelist.render(context)
  File "J:\arno\pythonenv\lib\site-packages\django\template\base.py", line 903, in render
    bit = self.render_node(node, context)
  File "J:\arno\pythonenv\lib\site-packages\django\template\debug.py", line 79, in render_node
    return node.render(context)
  File "J:\arno\pythonenv\lib\site-packages\django\template\base.py", line 1271, in render
    _dict = func(*resolved_args, **resolved_kwargs)
  File "J:\arno\pythonenv\lib\site-packages\django\contrib\admin\templatetags\admin_list.py", line 320, in result_list
    'results': list(results(cl))}
  File "J:\arno\pythonenv\lib\site-packages\django\contrib\admin\templatetags\admin_list.py", line 296, in results
    yield ResultList(None, items_for_result(cl, res, None))
  File "J:\arno\pythonenv\lib\site-packages\django\contrib\admin\templatetags\admin_list.py", line 287, in __init__
    super(ResultList, self).__init__(*items)
  File "J:\arno\pythonenv\lib\site-packages\django\contrib\admin\templatetags\admin_list.py", line 199, in items_for_result
    f, attr, value = lookup_field(field_name, result, cl.model_admin)
  File "J:\arno\pythonenv\lib\site-packages\django\contrib\admin\utils.py", line 282, in lookup_field
    value = attr()
  File "J:\arno\pythonenv\phx_web\monitor\models.py", line 21, in __str__
    return " - ".join([product, project, minion_id])
NameError: global name 'product' is not defined
2018-01-27 15:23:11,904 base.py [django.request:256] [ERROR]- Internal Server Error: /
Traceback (most recent call last):
  File "J:\arno\pythonenv\lib\site-packages\django\core\handlers\base.py", line 119, in get_response
    resolver_match = resolver.resolve(request.path_info)
  File "J:\arno\pythonenv\lib\site-packages\django\core\urlresolvers.py", line 366, in resolve
    for pattern in self.url_patterns:
  File "J:\arno\pythonenv\lib\site-packages\django\core\urlresolvers.py", line 402, in url_patterns
    patterns = getattr(self.urlconf_module, "urlpatterns", self.urlconf_module)
  File "J:\arno\pythonenv\lib\site-packages\django\core\urlresolvers.py", line 396, in urlconf_module
    self._urlconf_module = import_module(self.urlconf_name)
  File "c:\python27\Lib\importlib\__init__.py", line 37, in import_module
    __import__(name)
  File "J:\arno\pythonenv\phx_web\phxweb\urls.py", line 17, in <module>
    url(r'^', include('monitor.urls')),
  File "J:\arno\pythonenv\lib\site-packages\django\conf\urls\__init__.py", line 33, in include
    urlconf_module = import_module(urlconf_module)
  File "c:\python27\Lib\importlib\__init__.py", line 37, in import_module
    __import__(name)
  File "J:\arno\pythonenv\phx_web\monitor\urls.py", line 3, in <module>
    from . import views
  File "J:\arno\pythonenv\phx_web\monitor\views.py", line 8, in <module>
    from .project import *
  File "J:\arno\pythonenv\phx_web\monitor\project.py", line 44
    tmp_dict = {}
                ^
IndentationError: unindent does not match any outer indentation level
2018-01-27 15:23:54,954 base.py [django.request:256] [ERROR]- Internal Server Error: /
Traceback (most recent call last):
  File "J:\arno\pythonenv\lib\site-packages\django\core\handlers\base.py", line 119, in get_response
    resolver_match = resolver.resolve(request.path_info)
  File "J:\arno\pythonenv\lib\site-packages\django\core\urlresolvers.py", line 366, in resolve
    for pattern in self.url_patterns:
  File "J:\arno\pythonenv\lib\site-packages\django\core\urlresolvers.py", line 402, in url_patterns
    patterns = getattr(self.urlconf_module, "urlpatterns", self.urlconf_module)
  File "J:\arno\pythonenv\lib\site-packages\django\core\urlresolvers.py", line 396, in urlconf_module
    self._urlconf_module = import_module(self.urlconf_name)
  File "c:\python27\Lib\importlib\__init__.py", line 37, in import_module
    __import__(name)
  File "J:\arno\pythonenv\phx_web\phxweb\urls.py", line 17, in <module>
    url(r'^', include('monitor.urls')),
  File "J:\arno\pythonenv\lib\site-packages\django\conf\urls\__init__.py", line 33, in include
    urlconf_module = import_module(urlconf_module)
  File "c:\python27\Lib\importlib\__init__.py", line 37, in import_module
    __import__(name)
  File "J:\arno\pythonenv\phx_web\monitor\urls.py", line 3, in <module>
    from . import views
  File "J:\arno\pythonenv\phx_web\monitor\views.py", line 8, in <module>
    from .project import *
  File "J:\arno\pythonenv\phx_web\monitor\project.py", line 43
    tmp_dict = {}
                ^
IndentationError: unindent does not match any outer indentation level
2018-01-27 15:23:56,046 base.py [django.request:256] [ERROR]- Internal Server Error: /
Traceback (most recent call last):
  File "J:\arno\pythonenv\lib\site-packages\django\core\handlers\base.py", line 119, in get_response
    resolver_match = resolver.resolve(request.path_info)
  File "J:\arno\pythonenv\lib\site-packages\django\core\urlresolvers.py", line 366, in resolve
    for pattern in self.url_patterns:
  File "J:\arno\pythonenv\lib\site-packages\django\core\urlresolvers.py", line 402, in url_patterns
    patterns = getattr(self.urlconf_module, "urlpatterns", self.urlconf_module)
  File "J:\arno\pythonenv\lib\site-packages\django\core\urlresolvers.py", line 396, in urlconf_module
    self._urlconf_module = import_module(self.urlconf_name)
  File "c:\python27\Lib\importlib\__init__.py", line 37, in import_module
    __import__(name)
  File "J:\arno\pythonenv\phx_web\phxweb\urls.py", line 17, in <module>
    url(r'^', include('monitor.urls')),
  File "J:\arno\pythonenv\lib\site-packages\django\conf\urls\__init__.py", line 33, in include
    urlconf_module = import_module(urlconf_module)
  File "c:\python27\Lib\importlib\__init__.py", line 37, in import_module
    __import__(name)
  File "J:\arno\pythonenv\phx_web\monitor\urls.py", line 3, in <module>
    from . import views
  File "J:\arno\pythonenv\phx_web\monitor\views.py", line 8, in <module>
    from .project import *
  File "J:\arno\pythonenv\phx_web\monitor\project.py", line 43
    tmp_dict = {}
                ^
IndentationError: unindent does not match any outer indentation level
2018-01-27 15:24:22,332 base.py [django.request:256] [ERROR]- Internal Server Error: /
Traceback (most recent call last):
  File "J:\arno\pythonenv\lib\site-packages\django\core\handlers\base.py", line 119, in get_response
    resolver_match = resolver.resolve(request.path_info)
  File "J:\arno\pythonenv\lib\site-packages\django\core\urlresolvers.py", line 366, in resolve
    for pattern in self.url_patterns:
  File "J:\arno\pythonenv\lib\site-packages\django\core\urlresolvers.py", line 402, in url_patterns
    patterns = getattr(self.urlconf_module, "urlpatterns", self.urlconf_module)
  File "J:\arno\pythonenv\lib\site-packages\django\core\urlresolvers.py", line 396, in urlconf_module
    self._urlconf_module = import_module(self.urlconf_name)
  File "c:\python27\Lib\importlib\__init__.py", line 37, in import_module
    __import__(name)
  File "J:\arno\pythonenv\phx_web\phxweb\urls.py", line 17, in <module>
    url(r'^', include('monitor.urls')),
  File "J:\arno\pythonenv\lib\site-packages\django\conf\urls\__init__.py", line 33, in include
    urlconf_module = import_module(urlconf_module)
  File "c:\python27\Lib\importlib\__init__.py", line 37, in import_module
    __import__(name)
  File "J:\arno\pythonenv\phx_web\monitor\urls.py", line 3, in <module>
    from . import views
  File "J:\arno\pythonenv\phx_web\monitor\views.py", line 8, in <module>
    from .project import *
  File "J:\arno\pythonenv\phx_web\monitor\project.py", line 56
    return HttpResponse(json.dumps(project_list))
                                                ^
IndentationError: unindent does not match any outer indentation level
2018-01-27 15:24:23,424 base.py [django.request:256] [ERROR]- Internal Server Error: /
Traceback (most recent call last):
  File "J:\arno\pythonenv\lib\site-packages\django\core\handlers\base.py", line 119, in get_response
    resolver_match = resolver.resolve(request.path_info)
  File "J:\arno\pythonenv\lib\site-packages\django\core\urlresolvers.py", line 366, in resolve
    for pattern in self.url_patterns:
  File "J:\arno\pythonenv\lib\site-packages\django\core\urlresolvers.py", line 402, in url_patterns
    patterns = getattr(self.urlconf_module, "urlpatterns", self.urlconf_module)
  File "J:\arno\pythonenv\lib\site-packages\django\core\urlresolvers.py", line 396, in urlconf_module
    self._urlconf_module = import_module(self.urlconf_name)
  File "c:\python27\Lib\importlib\__init__.py", line 37, in import_module
    __import__(name)
  File "J:\arno\pythonenv\phx_web\phxweb\urls.py", line 17, in <module>
    url(r'^', include('monitor.urls')),
  File "J:\arno\pythonenv\lib\site-packages\django\conf\urls\__init__.py", line 33, in include
    urlconf_module = import_module(urlconf_module)
  File "c:\python27\Lib\importlib\__init__.py", line 37, in import_module
    __import__(name)
  File "J:\arno\pythonenv\phx_web\monitor\urls.py", line 3, in <module>
    from . import views
  File "J:\arno\pythonenv\phx_web\monitor\views.py", line 8, in <module>
    from .project import *
  File "J:\arno\pythonenv\phx_web\monitor\project.py", line 56
    return HttpResponse(json.dumps(project_list))
                                                ^
IndentationError: unindent does not match any outer indentation level
2018-01-27 15:24:43,838 base.py [django.request:256] [ERROR]- Internal Server Error: /
Traceback (most recent call last):
  File "J:\arno\pythonenv\lib\site-packages\django\core\handlers\base.py", line 119, in get_response
    resolver_match = resolver.resolve(request.path_info)
  File "J:\arno\pythonenv\lib\site-packages\django\core\urlresolvers.py", line 366, in resolve
    for pattern in self.url_patterns:
  File "J:\arno\pythonenv\lib\site-packages\django\core\urlresolvers.py", line 402, in url_patterns
    patterns = getattr(self.urlconf_module, "urlpatterns", self.urlconf_module)
  File "J:\arno\pythonenv\lib\site-packages\django\core\urlresolvers.py", line 396, in urlconf_module
    self._urlconf_module = import_module(self.urlconf_name)
  File "c:\python27\Lib\importlib\__init__.py", line 37, in import_module
    __import__(name)
  File "J:\arno\pythonenv\phx_web\phxweb\urls.py", line 17, in <module>
    url(r'^', include('monitor.urls')),
  File "J:\arno\pythonenv\lib\site-packages\django\conf\urls\__init__.py", line 33, in include
    urlconf_module = import_module(urlconf_module)
  File "c:\python27\Lib\importlib\__init__.py", line 37, in import_module
    __import__(name)
  File "J:\arno\pythonenv\phx_web\monitor\urls.py", line 3, in <module>
    from . import views
  File "J:\arno\pythonenv\phx_web\monitor\views.py", line 8, in <module>
    from .project import *
  File "J:\arno\pythonenv\phx_web\monitor\project.py", line 56
    return HttpResponse(json.dumps(project_list))
                                                ^
IndentationError: unindent does not match any outer indentation level
2018-01-27 15:24:44,655 base.py [django.request:256] [ERROR]- Internal Server Error: /
Traceback (most recent call last):
  File "J:\arno\pythonenv\lib\site-packages\django\core\handlers\base.py", line 119, in get_response
    resolver_match = resolver.resolve(request.path_info)
  File "J:\arno\pythonenv\lib\site-packages\django\core\urlresolvers.py", line 366, in resolve
    for pattern in self.url_patterns:
  File "J:\arno\pythonenv\lib\site-packages\django\core\urlresolvers.py", line 402, in url_patterns
    patterns = getattr(self.urlconf_module, "urlpatterns", self.urlconf_module)
  File "J:\arno\pythonenv\lib\site-packages\django\core\urlresolvers.py", line 396, in urlconf_module
    self._urlconf_module = import_module(self.urlconf_name)
  File "c:\python27\Lib\importlib\__init__.py", line 37, in import_module
    __import__(name)
  File "J:\arno\pythonenv\phx_web\phxweb\urls.py", line 17, in <module>
    url(r'^', include('monitor.urls')),
  File "J:\arno\pythonenv\lib\site-packages\django\conf\urls\__init__.py", line 33, in include
    urlconf_module = import_module(urlconf_module)
  File "c:\python27\Lib\importlib\__init__.py", line 37, in import_module
    __import__(name)
  File "J:\arno\pythonenv\phx_web\monitor\urls.py", line 3, in <module>
    from . import views
  File "J:\arno\pythonenv\phx_web\monitor\views.py", line 8, in <module>
    from .project import *
  File "J:\arno\pythonenv\phx_web\monitor\project.py", line 56
    return HttpResponse(json.dumps(project_list))
                                                ^
IndentationError: unindent does not match any outer indentation level
2018-01-27 15:25:06,832 base.py [django.request:256] [ERROR]- Internal Server Error: /
Traceback (most recent call last):
  File "J:\arno\pythonenv\lib\site-packages\django\core\handlers\base.py", line 119, in get_response
    resolver_match = resolver.resolve(request.path_info)
  File "J:\arno\pythonenv\lib\site-packages\django\core\urlresolvers.py", line 366, in resolve
    for pattern in self.url_patterns:
  File "J:\arno\pythonenv\lib\site-packages\django\core\urlresolvers.py", line 402, in url_patterns
    patterns = getattr(self.urlconf_module, "urlpatterns", self.urlconf_module)
  File "J:\arno\pythonenv\lib\site-packages\django\core\urlresolvers.py", line 396, in urlconf_module
    self._urlconf_module = import_module(self.urlconf_name)
  File "c:\python27\Lib\importlib\__init__.py", line 37, in import_module
    __import__(name)
  File "J:\arno\pythonenv\phx_web\phxweb\urls.py", line 17, in <module>
    url(r'^', include('monitor.urls')),
  File "J:\arno\pythonenv\lib\site-packages\django\conf\urls\__init__.py", line 33, in include
    urlconf_module = import_module(urlconf_module)
  File "c:\python27\Lib\importlib\__init__.py", line 37, in import_module
    __import__(name)
  File "J:\arno\pythonenv\phx_web\monitor\urls.py", line 3, in <module>
    from . import views
  File "J:\arno\pythonenv\phx_web\monitor\views.py", line 8, in <module>
    from .project import *
  File "J:\arno\pythonenv\phx_web\monitor\project.py", line 56
    return HttpResponse(json.dumps(project_list))
                                                ^
IndentationError: unindent does not match any outer indentation level
2018-01-27 15:25:07,551 base.py [django.request:256] [ERROR]- Internal Server Error: /
Traceback (most recent call last):
  File "J:\arno\pythonenv\lib\site-packages\django\core\handlers\base.py", line 119, in get_response
    resolver_match = resolver.resolve(request.path_info)
  File "J:\arno\pythonenv\lib\site-packages\django\core\urlresolvers.py", line 366, in resolve
    for pattern in self.url_patterns:
  File "J:\arno\pythonenv\lib\site-packages\django\core\urlresolvers.py", line 402, in url_patterns
    patterns = getattr(self.urlconf_module, "urlpatterns", self.urlconf_module)
  File "J:\arno\pythonenv\lib\site-packages\django\core\urlresolvers.py", line 396, in urlconf_module
    self._urlconf_module = import_module(self.urlconf_name)
  File "c:\python27\Lib\importlib\__init__.py", line 37, in import_module
    __import__(name)
  File "J:\arno\pythonenv\phx_web\phxweb\urls.py", line 17, in <module>
    url(r'^', include('monitor.urls')),
  File "J:\arno\pythonenv\lib\site-packages\django\conf\urls\__init__.py", line 33, in include
    urlconf_module = import_module(urlconf_module)
  File "c:\python27\Lib\importlib\__init__.py", line 37, in import_module
    __import__(name)
  File "J:\arno\pythonenv\phx_web\monitor\urls.py", line 3, in <module>
    from . import views
  File "J:\arno\pythonenv\phx_web\monitor\views.py", line 8, in <module>
    from .project import *
  File "J:\arno\pythonenv\phx_web\monitor\project.py", line 56
    return HttpResponse(json.dumps(project_list))
                                                ^
IndentationError: unindent does not match any outer indentation level
2018-01-27 15:25:08,003 base.py [django.request:256] [ERROR]- Internal Server Error: /
Traceback (most recent call last):
  File "J:\arno\pythonenv\lib\site-packages\django\core\handlers\base.py", line 119, in get_response
    resolver_match = resolver.resolve(request.path_info)
  File "J:\arno\pythonenv\lib\site-packages\django\core\urlresolvers.py", line 366, in resolve
    for pattern in self.url_patterns:
  File "J:\arno\pythonenv\lib\site-packages\django\core\urlresolvers.py", line 402, in url_patterns
    patterns = getattr(self.urlconf_module, "urlpatterns", self.urlconf_module)
  File "J:\arno\pythonenv\lib\site-packages\django\core\urlresolvers.py", line 396, in urlconf_module
    self._urlconf_module = import_module(self.urlconf_name)
  File "c:\python27\Lib\importlib\__init__.py", line 37, in import_module
    __import__(name)
  File "J:\arno\pythonenv\phx_web\phxweb\urls.py", line 17, in <module>
    url(r'^', include('monitor.urls')),
  File "J:\arno\pythonenv\lib\site-packages\django\conf\urls\__init__.py", line 33, in include
    urlconf_module = import_module(urlconf_module)
  File "c:\python27\Lib\importlib\__init__.py", line 37, in import_module
    __import__(name)
  File "J:\arno\pythonenv\phx_web\monitor\urls.py", line 3, in <module>
    from . import views
  File "J:\arno\pythonenv\phx_web\monitor\views.py", line 8, in <module>
    from .project import *
  File "J:\arno\pythonenv\phx_web\monitor\project.py", line 56
    return HttpResponse(json.dumps(project_list))
                                                ^
IndentationError: unindent does not match any outer indentation level
2018-01-27 15:25:08,391 base.py [django.request:256] [ERROR]- Internal Server Error: /
Traceback (most recent call last):
  File "J:\arno\pythonenv\lib\site-packages\django\core\handlers\base.py", line 119, in get_response
    resolver_match = resolver.resolve(request.path_info)
  File "J:\arno\pythonenv\lib\site-packages\django\core\urlresolvers.py", line 366, in resolve
    for pattern in self.url_patterns:
  File "J:\arno\pythonenv\lib\site-packages\django\core\urlresolvers.py", line 402, in url_patterns
    patterns = getattr(self.urlconf_module, "urlpatterns", self.urlconf_module)
  File "J:\arno\pythonenv\lib\site-packages\django\core\urlresolvers.py", line 396, in urlconf_module
    self._urlconf_module = import_module(self.urlconf_name)
  File "c:\python27\Lib\importlib\__init__.py", line 37, in import_module
    __import__(name)
  File "J:\arno\pythonenv\phx_web\phxweb\urls.py", line 17, in <module>
    url(r'^', include('monitor.urls')),
  File "J:\arno\pythonenv\lib\site-packages\django\conf\urls\__init__.py", line 33, in include
    urlconf_module = import_module(urlconf_module)
  File "c:\python27\Lib\importlib\__init__.py", line 37, in import_module
    __import__(name)
  File "J:\arno\pythonenv\phx_web\monitor\urls.py", line 3, in <module>
    from . import views
  File "J:\arno\pythonenv\phx_web\monitor\views.py", line 8, in <module>
    from .project import *
  File "J:\arno\pythonenv\phx_web\monitor\project.py", line 56
    return HttpResponse(json.dumps(project_list))
                                                ^
IndentationError: unindent does not match any outer indentation level
2018-01-27 15:25:08,624 base.py [django.request:256] [ERROR]- Internal Server Error: /
Traceback (most recent call last):
  File "J:\arno\pythonenv\lib\site-packages\django\core\handlers\base.py", line 119, in get_response
    resolver_match = resolver.resolve(request.path_info)
  File "J:\arno\pythonenv\lib\site-packages\django\core\urlresolvers.py", line 366, in resolve
    for pattern in self.url_patterns:
  File "J:\arno\pythonenv\lib\site-packages\django\core\urlresolvers.py", line 402, in url_patterns
    patterns = getattr(self.urlconf_module, "urlpatterns", self.urlconf_module)
  File "J:\arno\pythonenv\lib\site-packages\django\core\urlresolvers.py", line 396, in urlconf_module
    self._urlconf_module = import_module(self.urlconf_name)
  File "c:\python27\Lib\importlib\__init__.py", line 37, in import_module
    __import__(name)
  File "J:\arno\pythonenv\phx_web\phxweb\urls.py", line 17, in <module>
    url(r'^', include('monitor.urls')),
  File "J:\arno\pythonenv\lib\site-packages\django\conf\urls\__init__.py", line 33, in include
    urlconf_module = import_module(urlconf_module)
  File "c:\python27\Lib\importlib\__init__.py", line 37, in import_module
    __import__(name)
  File "J:\arno\pythonenv\phx_web\monitor\urls.py", line 3, in <module>
    from . import views
  File "J:\arno\pythonenv\phx_web\monitor\views.py", line 8, in <module>
    from .project import *
  File "J:\arno\pythonenv\phx_web\monitor\project.py", line 56
    return HttpResponse(json.dumps(project_list))
                                                ^
IndentationError: unindent does not match any outer indentation level
2018-01-27 15:25:41,467 base.py [django.request:256] [ERROR]- Internal Server Error: /
Traceback (most recent call last):
  File "J:\arno\pythonenv\lib\site-packages\django\core\handlers\base.py", line 119, in get_response
    resolver_match = resolver.resolve(request.path_info)
  File "J:\arno\pythonenv\lib\site-packages\django\core\urlresolvers.py", line 366, in resolve
    for pattern in self.url_patterns:
  File "J:\arno\pythonenv\lib\site-packages\django\core\urlresolvers.py", line 402, in url_patterns
    patterns = getattr(self.urlconf_module, "urlpatterns", self.urlconf_module)
  File "J:\arno\pythonenv\lib\site-packages\django\core\urlresolvers.py", line 396, in urlconf_module
    self._urlconf_module = import_module(self.urlconf_name)
  File "c:\python27\Lib\importlib\__init__.py", line 37, in import_module
    __import__(name)
  File "J:\arno\pythonenv\phx_web\phxweb\urls.py", line 17, in <module>
    url(r'^', include('monitor.urls')),
  File "J:\arno\pythonenv\lib\site-packages\django\conf\urls\__init__.py", line 33, in include
    urlconf_module = import_module(urlconf_module)
  File "c:\python27\Lib\importlib\__init__.py", line 37, in import_module
    __import__(name)
  File "J:\arno\pythonenv\phx_web\monitor\urls.py", line 3, in <module>
    from . import views
  File "J:\arno\pythonenv\phx_web\monitor\views.py", line 8, in <module>
    from .project import *
  File "J:\arno\pythonenv\phx_web\monitor\project.py", line 56
    return HttpResponse(json.dumps(project_list))
                                                ^
IndentationError: unindent does not match any outer indentation level
2018-01-27 15:25:42,312 base.py [django.request:256] [ERROR]- Internal Server Error: /
Traceback (most recent call last):
  File "J:\arno\pythonenv\lib\site-packages\django\core\handlers\base.py", line 119, in get_response
    resolver_match = resolver.resolve(request.path_info)
  File "J:\arno\pythonenv\lib\site-packages\django\core\urlresolvers.py", line 366, in resolve
    for pattern in self.url_patterns:
  File "J:\arno\pythonenv\lib\site-packages\django\core\urlresolvers.py", line 402, in url_patterns
    patterns = getattr(self.urlconf_module, "urlpatterns", self.urlconf_module)
  File "J:\arno\pythonenv\lib\site-packages\django\core\urlresolvers.py", line 396, in urlconf_module
    self._urlconf_module = import_module(self.urlconf_name)
  File "c:\python27\Lib\importlib\__init__.py", line 37, in import_module
    __import__(name)
  File "J:\arno\pythonenv\phx_web\phxweb\urls.py", line 17, in <module>
    url(r'^', include('monitor.urls')),
  File "J:\arno\pythonenv\lib\site-packages\django\conf\urls\__init__.py", line 33, in include
    urlconf_module = import_module(urlconf_module)
  File "c:\python27\Lib\importlib\__init__.py", line 37, in import_module
    __import__(name)
  File "J:\arno\pythonenv\phx_web\monitor\urls.py", line 3, in <module>
    from . import views
  File "J:\arno\pythonenv\phx_web\monitor\views.py", line 8, in <module>
    from .project import *
  File "J:\arno\pythonenv\phx_web\monitor\project.py", line 56
    return HttpResponse(json.dumps(project_list))
                                                ^
IndentationError: unindent does not match any outer indentation level
2018-01-27 15:27:02,453 base.py [django.request:256] [ERROR]- Internal Server Error: /
Traceback (most recent call last):
  File "J:\arno\pythonenv\lib\site-packages\django\core\handlers\base.py", line 119, in get_response
    resolver_match = resolver.resolve(request.path_info)
  File "J:\arno\pythonenv\lib\site-packages\django\core\urlresolvers.py", line 366, in resolve
    for pattern in self.url_patterns:
  File "J:\arno\pythonenv\lib\site-packages\django\core\urlresolvers.py", line 402, in url_patterns
    patterns = getattr(self.urlconf_module, "urlpatterns", self.urlconf_module)
  File "J:\arno\pythonenv\lib\site-packages\django\core\urlresolvers.py", line 396, in urlconf_module
    self._urlconf_module = import_module(self.urlconf_name)
  File "c:\python27\Lib\importlib\__init__.py", line 37, in import_module
    __import__(name)
  File "J:\arno\pythonenv\phx_web\phxweb\urls.py", line 17, in <module>
    url(r'^', include('monitor.urls')),
  File "J:\arno\pythonenv\lib\site-packages\django\conf\urls\__init__.py", line 33, in include
    urlconf_module = import_module(urlconf_module)
  File "c:\python27\Lib\importlib\__init__.py", line 37, in import_module
    __import__(name)
  File "J:\arno\pythonenv\phx_web\monitor\urls.py", line 3, in <module>
    from . import views
  File "J:\arno\pythonenv\phx_web\monitor\views.py", line 8, in <module>
    from .project import *
  File "J:\arno\pythonenv\phx_web\monitor\project.py", line 5, in <module>
    from dwebsocket import require_websocket
ImportError: No module named dwebsocket
2018-01-27 15:27:34,829 base.py [django.request:256] [ERROR]- Internal Server Error: /
Traceback (most recent call last):
  File "J:\arno\pythonenv\lib\site-packages\django\core\handlers\base.py", line 119, in get_response
    resolver_match = resolver.resolve(request.path_info)
  File "J:\arno\pythonenv\lib\site-packages\django\core\urlresolvers.py", line 366, in resolve
    for pattern in self.url_patterns:
  File "J:\arno\pythonenv\lib\site-packages\django\core\urlresolvers.py", line 402, in url_patterns
    patterns = getattr(self.urlconf_module, "urlpatterns", self.urlconf_module)
  File "J:\arno\pythonenv\lib\site-packages\django\core\urlresolvers.py", line 396, in urlconf_module
    self._urlconf_module = import_module(self.urlconf_name)
  File "c:\python27\Lib\importlib\__init__.py", line 37, in import_module
    __import__(name)
  File "J:\arno\pythonenv\phx_web\phxweb\urls.py", line 17, in <module>
    url(r'^', include('monitor.urls')),
  File "J:\arno\pythonenv\lib\site-packages\django\conf\urls\__init__.py", line 33, in include
    urlconf_module = import_module(urlconf_module)
  File "c:\python27\Lib\importlib\__init__.py", line 37, in import_module
    __import__(name)
  File "J:\arno\pythonenv\phx_web\monitor\urls.py", line 3, in <module>
    from . import views
  File "J:\arno\pythonenv\phx_web\monitor\views.py", line 8, in <module>
    from .project import *
  File "J:\arno\pythonenv\phx_web\monitor\project.py", line 7, in <module>
    from models import project_t, monion_t
ImportError: cannot import name monion_t
2018-01-27 15:27:46,994 base.py [django.request:256] [ERROR]- Internal Server Error: /
Traceback (most recent call last):
  File "J:\arno\pythonenv\lib\site-packages\django\core\handlers\base.py", line 119, in get_response
    resolver_match = resolver.resolve(request.path_info)
  File "J:\arno\pythonenv\lib\site-packages\django\core\urlresolvers.py", line 366, in resolve
    for pattern in self.url_patterns:
  File "J:\arno\pythonenv\lib\site-packages\django\core\urlresolvers.py", line 402, in url_patterns
    patterns = getattr(self.urlconf_module, "urlpatterns", self.urlconf_module)
  File "J:\arno\pythonenv\lib\site-packages\django\core\urlresolvers.py", line 396, in urlconf_module
    self._urlconf_module = import_module(self.urlconf_name)
  File "c:\python27\Lib\importlib\__init__.py", line 37, in import_module
    __import__(name)
  File "J:\arno\pythonenv\phx_web\phxweb\urls.py", line 17, in <module>
    url(r'^', include('monitor.urls')),
  File "J:\arno\pythonenv\lib\site-packages\django\conf\urls\__init__.py", line 33, in include
    urlconf_module = import_module(urlconf_module)
  File "c:\python27\Lib\importlib\__init__.py", line 37, in import_module
    __import__(name)
  File "J:\arno\pythonenv\phx_web\monitor\urls.py", line 3, in <module>
    from . import views
  File "J:\arno\pythonenv\phx_web\monitor\views.py", line 8, in <module>
    from .project import *
  File "J:\arno\pythonenv\phx_web\monitor\project.py", line 9, in <module>
    import json, logging, requests, re, datetime
ImportError: No module named requests
2018-01-27 15:28:22,607 base.py [django.request:256] [ERROR]- Internal Server Error: /monitor/project/Query
Traceback (most recent call last):
  File "J:\arno\pythonenv\lib\site-packages\django\core\handlers\base.py", line 132, in get_response
    response = wrapped_callback(request, *callback_args, **callback_kwargs)
  File "J:\arno\pythonenv\lib\site-packages\django\views\decorators\csrf.py", line 58, in wrapped_view
    return view_func(*args, **kwargs)
  File "J:\arno\pythonenv\phx_web\monitor\project.py", line 27, in ProjectQuery
    datas = tomcat_url.objects.all()
NameError: global name 'tomcat_url' is not defined
2018-01-27 15:29:11,717 base.py [django.request:256] [ERROR]- Internal Server Error: /monitor/project/Query
Traceback (most recent call last):
  File "J:\arno\pythonenv\lib\site-packages\django\core\handlers\base.py", line 132, in get_response
    response = wrapped_callback(request, *callback_args, **callback_kwargs)
  File "J:\arno\pythonenv\lib\site-packages\django\views\decorators\csrf.py", line 58, in wrapped_view
    return view_func(*args, **kwargs)
  File "J:\arno\pythonenv\phx_web\monitor\project.py", line 34, in ProjectQuery
    logger.info('æŸ¥è¯¢å‚æ•°ï¼š%s' %act)
UnicodeDecodeError: 'ascii' codec can't decode byte 0xe6 in position 0: ordinal not in range(128)
