2018-06-04 18:38:19,947 - INFO - Received signal 2 (SIGINT), stopping...
2018-06-04 18:38:20,194 - WARNING - Exiting immediately!
2018-06-04 18:50:37,154 - INFO - Received signal 2 (SIGINT), stopping...
2018-06-04 18:50:37,338 - WARNING - Exiting immediately!
2018-06-04 18:58:00,065 - WARNING - A TelegramError was raised while processing the Update
2018-06-04 18:58:00,065 - ERROR - No error handlers are registered, logging exception...
Traceback (most recent call last):
  File "J:\arno\test\lib\site-packages\telegram\ext\dispatcher.py", line 279, in process_update
    handler.handle_update(update, self)
  File "J:\arno\test\lib\site-packages\telegram\ext\commandhandler.py", line 173, in handle_update
    return self.callback(dispatcher.bot, update, **optional_args)
  File "telegram_bot.py", line 17, in start
    update.message.reply_text("Welcome to my awesome bot!")
  File "J:\arno\test\lib\site-packages\telegram\message.py", line 432, in reply_text
    return self.bot.send_message(self.chat_id, *args, **kwargs)
  File "J:\arno\test\lib\site-packages\telegram\bot.py", line 60, in decorator
    result = func(self, *args, **kwargs)
  File "J:\arno\test\lib\site-packages\telegram\bot.py", line 85, in decorator
    result = self._request.post(url, data, timeout=kwargs.get('timeout'))
  File "J:\arno\test\lib\site-packages\telegram\utils\request.py", line 278, in post
    **urlopen_kwargs)
  File "J:\arno\test\lib\site-packages\telegram\utils\request.py", line 197, in _request_wrapper
    raise TimedOut()
TimedOut: Timed out
2018-06-04 19:03:19,198 - ERROR - An uncaught error was raised while processing the update
Traceback (most recent call last):
  File "J:\arno\test\lib\site-packages\telegram\ext\dispatcher.py", line 279, in process_update
    handler.handle_update(update, self)
  File "J:\arno\test\lib\site-packages\telegram\ext\commandhandler.py", line 173, in handle_update
    return self.callback(dispatcher.bot, update, **optional_args)
  File "telegram_bot.py", line 21, in start
    reply_markup=ReplyKeyboardMarkup(reply_keyboard)
NameError: global name 'ReplyKeyboardMarkup' is not defined
2018-06-04 19:03:46,680 - ERROR - An uncaught error was raised while processing the update
Traceback (most recent call last):
  File "J:\arno\test\lib\site-packages\telegram\ext\dispatcher.py", line 279, in process_update
    handler.handle_update(update, self)
  File "J:\arno\test\lib\site-packages\telegram\ext\commandhandler.py", line 173, in handle_update
    return self.callback(dispatcher.bot, update, **optional_args)
  File "telegram_bot.py", line 21, in start
    reply_markup=ReplyKeyboardMarkup(reply_keyboard)
NameError: global name 'ReplyKeyboardMarkup' is not defined
2018-06-04 19:04:54,026 - INFO - Received signal 2 (SIGINT), stopping...
2018-06-04 19:04:54,210 - WARNING - Exiting immediately!
2018-06-04 19:05:00,348 - ERROR - An uncaught error was raised while processing the update
Traceback (most recent call last):
  File "J:\arno\test\lib\site-packages\telegram\ext\dispatcher.py", line 279, in process_update
    handler.handle_update(update, self)
  File "J:\arno\test\lib\site-packages\telegram\ext\commandhandler.py", line 173, in handle_update
    return self.callback(dispatcher.bot, update, **optional_args)
  File "telegram_bot.py", line 21, in start
    reply_markup=ReplyKeyboardMarkup(reply_keyboard)
NameError: global name 'ReplyKeyboardMarkup' is not defined
2018-06-04 19:05:41,658 - INFO - Received signal 2 (SIGINT), stopping...
2018-06-04 19:05:41,828 - WARNING - Exiting immediately!
2018-06-04 19:06:44,105 - INFO - Received signal 2 (SIGINT), stopping...
2018-06-04 19:06:52,345 - WARNING - Exiting immediately!
2018-06-04 19:18:07,795 - INFO - Received signal 2 (SIGINT), stopping...
2018-06-04 19:18:13,279 - WARNING - Exiting immediately!
2018-06-04 19:18:49,874 - INFO - Received signal 2 (SIGINT), stopping...
2018-06-04 19:18:50,073 - WARNING - Exiting immediately!
2018-06-04 19:25:03,736 - INFO - Received signal 2 (SIGINT), stopping...
2018-06-04 19:26:39,905 - INFO - Received signal 2 (SIGINT), stopping...
2018-06-04 19:26:40,075 - WARNING - Exiting immediately!
2018-06-04 19:27:24,114 - INFO - Received signal 2 (SIGINT), stopping...
2018-06-04 19:27:28,023 - WARNING - Exiting immediately!
2018-06-04 19:28:23,154 - INFO - Received signal 2 (SIGINT), stopping...
2018-06-04 19:28:23,338 - WARNING - Exiting immediately!
2018-06-04 19:29:33,785 - INFO - Received signal 2 (SIGINT), stopping...
2018-06-04 19:29:33,953 - WARNING - Exiting immediately!
2018-06-04 19:30:19,201 - INFO - Received signal 2 (SIGINT), stopping...
2018-06-04 19:30:29,250 - WARNING - Exiting immediately!
2018-06-04 19:30:46,072 - INFO - Received signal 2 (SIGINT), stopping...
2018-06-04 19:30:46,242 - WARNING - Exiting immediately!
2018-06-04 19:38:20,497 - INFO - Received signal 2 (SIGINT), stopping...
2018-06-04 19:38:20,667 - WARNING - Exiting immediately!
2018-06-04 19:38:31,224 - WARNING - A TelegramError was raised while processing the Update
2018-06-04 19:38:31,226 - ERROR - No error handlers are registered, logging exception...
Traceback (most recent call last):
  File "J:\arno\test\lib\site-packages\telegram\ext\dispatcher.py", line 279, in process_update
    handler.handle_update(update, self)
  File "J:\arno\test\lib\site-packages\telegram\ext\conversationhandler.py", line 305, in handle_update
    new_state = self.current_handler.handle_update(update, dispatcher)
  File "J:\arno\test\lib\site-packages\telegram\ext\regexhandler.py", line 173, in handle_update
    return self.callback(dispatcher.bot, update, **optional_args)
  File "telegram_bot.py", line 26, in end_option
    update.message.reply_text("", reply_markup=ReplyKeyboardRemove())
  File "J:\arno\test\lib\site-packages\telegram\message.py", line 432, in reply_text
    return self.bot.send_message(self.chat_id, *args, **kwargs)
  File "J:\arno\test\lib\site-packages\telegram\bot.py", line 60, in decorator
    result = func(self, *args, **kwargs)
  File "J:\arno\test\lib\site-packages\telegram\bot.py", line 85, in decorator
    result = self._request.post(url, data, timeout=kwargs.get('timeout'))
  File "J:\arno\test\lib\site-packages\telegram\utils\request.py", line 278, in post
    **urlopen_kwargs)
  File "J:\arno\test\lib\site-packages\telegram\utils\request.py", line 215, in _request_wrapper
    raise BadRequest(message)
BadRequest: Message text is empty
2018-06-04 19:38:31,480 - WARNING - A TelegramError was raised while processing the Update
2018-06-04 19:38:31,480 - ERROR - No error handlers are registered, logging exception...
Traceback (most recent call last):
  File "J:\arno\test\lib\site-packages\telegram\ext\dispatcher.py", line 279, in process_update
    handler.handle_update(update, self)
  File "J:\arno\test\lib\site-packages\telegram\ext\conversationhandler.py", line 305, in handle_update
    new_state = self.current_handler.handle_update(update, dispatcher)
  File "J:\arno\test\lib\site-packages\telegram\ext\regexhandler.py", line 173, in handle_update
    return self.callback(dispatcher.bot, update, **optional_args)
  File "telegram_bot.py", line 26, in end_option
    update.message.reply_text("", reply_markup=ReplyKeyboardRemove())
  File "J:\arno\test\lib\site-packages\telegram\message.py", line 432, in reply_text
    return self.bot.send_message(self.chat_id, *args, **kwargs)
  File "J:\arno\test\lib\site-packages\telegram\bot.py", line 60, in decorator
    result = func(self, *args, **kwargs)
  File "J:\arno\test\lib\site-packages\telegram\bot.py", line 85, in decorator
    result = self._request.post(url, data, timeout=kwargs.get('timeout'))
  File "J:\arno\test\lib\site-packages\telegram\utils\request.py", line 278, in post
    **urlopen_kwargs)
  File "J:\arno\test\lib\site-packages\telegram\utils\request.py", line 215, in _request_wrapper
    raise BadRequest(message)
BadRequest: Message text is empty
2018-06-04 19:38:31,730 - WARNING - A TelegramError was raised while processing the Update
2018-06-04 19:38:31,732 - ERROR - No error handlers are registered, logging exception...
Traceback (most recent call last):
  File "J:\arno\test\lib\site-packages\telegram\ext\dispatcher.py", line 279, in process_update
    handler.handle_update(update, self)
  File "J:\arno\test\lib\site-packages\telegram\ext\conversationhandler.py", line 305, in handle_update
    new_state = self.current_handler.handle_update(update, dispatcher)
  File "J:\arno\test\lib\site-packages\telegram\ext\regexhandler.py", line 173, in handle_update
    return self.callback(dispatcher.bot, update, **optional_args)
  File "telegram_bot.py", line 26, in end_option
    update.message.reply_text("", reply_markup=ReplyKeyboardRemove())
  File "J:\arno\test\lib\site-packages\telegram\message.py", line 432, in reply_text
    return self.bot.send_message(self.chat_id, *args, **kwargs)
  File "J:\arno\test\lib\site-packages\telegram\bot.py", line 60, in decorator
    result = func(self, *args, **kwargs)
  File "J:\arno\test\lib\site-packages\telegram\bot.py", line 85, in decorator
    result = self._request.post(url, data, timeout=kwargs.get('timeout'))
  File "J:\arno\test\lib\site-packages\telegram\utils\request.py", line 278, in post
    **urlopen_kwargs)
  File "J:\arno\test\lib\site-packages\telegram\utils\request.py", line 215, in _request_wrapper
    raise BadRequest(message)
BadRequest: Message text is empty
2018-06-04 19:38:31,983 - WARNING - A TelegramError was raised while processing the Update
2018-06-04 19:38:31,983 - ERROR - No error handlers are registered, logging exception...
Traceback (most recent call last):
  File "J:\arno\test\lib\site-packages\telegram\ext\dispatcher.py", line 279, in process_update
    handler.handle_update(update, self)
  File "J:\arno\test\lib\site-packages\telegram\ext\conversationhandler.py", line 305, in handle_update
    new_state = self.current_handler.handle_update(update, dispatcher)
  File "J:\arno\test\lib\site-packages\telegram\ext\regexhandler.py", line 173, in handle_update
    return self.callback(dispatcher.bot, update, **optional_args)
  File "telegram_bot.py", line 26, in end_option
    update.message.reply_text("", reply_markup=ReplyKeyboardRemove())
  File "J:\arno\test\lib\site-packages\telegram\message.py", line 432, in reply_text
    return self.bot.send_message(self.chat_id, *args, **kwargs)
  File "J:\arno\test\lib\site-packages\telegram\bot.py", line 60, in decorator
    result = func(self, *args, **kwargs)
  File "J:\arno\test\lib\site-packages\telegram\bot.py", line 85, in decorator
    result = self._request.post(url, data, timeout=kwargs.get('timeout'))
  File "J:\arno\test\lib\site-packages\telegram\utils\request.py", line 278, in post
    **urlopen_kwargs)
  File "J:\arno\test\lib\site-packages\telegram\utils\request.py", line 215, in _request_wrapper
    raise BadRequest(message)
BadRequest: Message text is empty
2018-06-04 19:38:32,236 - WARNING - A TelegramError was raised while processing the Update
2018-06-04 19:38:32,236 - ERROR - No error handlers are registered, logging exception...
Traceback (most recent call last):
  File "J:\arno\test\lib\site-packages\telegram\ext\dispatcher.py", line 279, in process_update
    handler.handle_update(update, self)
  File "J:\arno\test\lib\site-packages\telegram\ext\conversationhandler.py", line 305, in handle_update
    new_state = self.current_handler.handle_update(update, dispatcher)
  File "J:\arno\test\lib\site-packages\telegram\ext\regexhandler.py", line 173, in handle_update
    return self.callback(dispatcher.bot, update, **optional_args)
  File "telegram_bot.py", line 26, in end_option
    update.message.reply_text("", reply_markup=ReplyKeyboardRemove())
  File "J:\arno\test\lib\site-packages\telegram\message.py", line 432, in reply_text
    return self.bot.send_message(self.chat_id, *args, **kwargs)
  File "J:\arno\test\lib\site-packages\telegram\bot.py", line 60, in decorator
    result = func(self, *args, **kwargs)
  File "J:\arno\test\lib\site-packages\telegram\bot.py", line 85, in decorator
    result = self._request.post(url, data, timeout=kwargs.get('timeout'))
  File "J:\arno\test\lib\site-packages\telegram\utils\request.py", line 278, in post
    **urlopen_kwargs)
  File "J:\arno\test\lib\site-packages\telegram\utils\request.py", line 215, in _request_wrapper
    raise BadRequest(message)
BadRequest: Message text is empty
2018-06-04 19:40:31,792 - INFO - Received signal 2 (SIGINT), stopping...
2018-06-04 19:40:31,946 - WARNING - Exiting immediately!
2018-06-04 19:40:39,684 - WARNING - A TelegramError was raised while processing the Update
2018-06-04 19:40:39,684 - ERROR - No error handlers are registered, logging exception...
Traceback (most recent call last):
  File "J:\arno\test\lib\site-packages\telegram\ext\dispatcher.py", line 279, in process_update
    handler.handle_update(update, self)
  File "J:\arno\test\lib\site-packages\telegram\ext\conversationhandler.py", line 305, in handle_update
    new_state = self.current_handler.handle_update(update, dispatcher)
  File "J:\arno\test\lib\site-packages\telegram\ext\regexhandler.py", line 173, in handle_update
    return self.callback(dispatcher.bot, update, **optional_args)
  File "telegram_bot.py", line 26, in end_option
    update.message.reply_text("", reply_markup=ReplyKeyboardRemove())
  File "J:\arno\test\lib\site-packages\telegram\message.py", line 432, in reply_text
    return self.bot.send_message(self.chat_id, *args, **kwargs)
  File "J:\arno\test\lib\site-packages\telegram\bot.py", line 60, in decorator
    result = func(self, *args, **kwargs)
  File "J:\arno\test\lib\site-packages\telegram\bot.py", line 85, in decorator
    result = self._request.post(url, data, timeout=kwargs.get('timeout'))
  File "J:\arno\test\lib\site-packages\telegram\utils\request.py", line 278, in post
    **urlopen_kwargs)
  File "J:\arno\test\lib\site-packages\telegram\utils\request.py", line 215, in _request_wrapper
    raise BadRequest(message)
BadRequest: Message text is empty
2018-06-04 19:40:41,742 - WARNING - A TelegramError was raised while processing the Update
2018-06-04 19:40:41,742 - ERROR - No error handlers are registered, logging exception...
Traceback (most recent call last):
  File "J:\arno\test\lib\site-packages\telegram\ext\dispatcher.py", line 279, in process_update
    handler.handle_update(update, self)
  File "J:\arno\test\lib\site-packages\telegram\ext\conversationhandler.py", line 305, in handle_update
    new_state = self.current_handler.handle_update(update, dispatcher)
  File "J:\arno\test\lib\site-packages\telegram\ext\regexhandler.py", line 173, in handle_update
    return self.callback(dispatcher.bot, update, **optional_args)
  File "telegram_bot.py", line 26, in end_option
    update.message.reply_text("", reply_markup=ReplyKeyboardRemove())
  File "J:\arno\test\lib\site-packages\telegram\message.py", line 432, in reply_text
    return self.bot.send_message(self.chat_id, *args, **kwargs)
  File "J:\arno\test\lib\site-packages\telegram\bot.py", line 60, in decorator
    result = func(self, *args, **kwargs)
  File "J:\arno\test\lib\site-packages\telegram\bot.py", line 85, in decorator
    result = self._request.post(url, data, timeout=kwargs.get('timeout'))
  File "J:\arno\test\lib\site-packages\telegram\utils\request.py", line 278, in post
    **urlopen_kwargs)
  File "J:\arno\test\lib\site-packages\telegram\utils\request.py", line 215, in _request_wrapper
    raise BadRequest(message)
BadRequest: Message text is empty
2018-06-04 19:40:50,312 - INFO - Received signal 2 (SIGINT), stopping...
2018-06-04 19:40:55,588 - WARNING - Exiting immediately!
2018-06-04 19:51:56,378 - INFO - Received signal 2 (SIGINT), stopping...
2018-06-04 19:51:56,520 - WARNING - Exiting immediately!
2018-06-04 20:02:14,194 - INFO - Received signal 2 (SIGINT), stopping...
2018-06-04 20:02:14,345 - WARNING - Exiting immediately!
2018-06-04 20:02:38,473 - INFO - Received signal 2 (SIGINT), stopping...
2018-06-04 20:02:38,641 - WARNING - Exiting immediately!
2018-06-04 20:04:06,065 - INFO - Received signal 2 (SIGINT), stopping...
2018-06-04 20:04:06,233 - WARNING - Exiting immediately!
2018-06-04 20:05:39,793 - INFO - Received signal 2 (SIGINT), stopping...
2018-06-04 20:05:39,953 - WARNING - Exiting immediately!
2018-06-04 20:06:00,986 - INFO - Received signal 2 (SIGINT), stopping...
2018-06-04 20:06:01,121 - WARNING - Exiting immediately!
2018-06-04 20:10:38,818 - INFO - Received signal 2 (SIGINT), stopping...
2018-06-04 20:10:38,984 - WARNING - Exiting immediately!
2018-06-04 20:15:03,369 - INFO - Received signal 2 (SIGINT), stopping...
2018-06-04 20:15:03,522 - WARNING - Exiting immediately!
2018-06-04 20:29:50,023 - ERROR - An uncaught error was raised while processing the update
Traceback (most recent call last):
  File "J:\arno\test\lib\site-packages\telegram\ext\dispatcher.py", line 278, in process_update
    for handler in (x for x in self.handlers[group] if x.check_update(update)):
  File "J:\arno\test\lib\site-packages\telegram\ext\dispatcher.py", line 278, in <genexpr>
    for handler in (x for x in self.handlers[group] if x.check_update(update)):
  File "J:\arno\test\lib\site-packages\telegram\ext\conversationhandler.py", line 264, in check_update
    if entry_point.check_update(update):
  File "J:\arno\test\lib\site-packages\telegram\ext\handler.py", line 85, in check_update
    raise NotImplementedError
NotImplementedError
2018-06-04 20:29:50,026 - ERROR - An uncaught error was raised while processing the update
Traceback (most recent call last):
  File "J:\arno\test\lib\site-packages\telegram\ext\dispatcher.py", line 278, in process_update
    for handler in (x for x in self.handlers[group] if x.check_update(update)):
  File "J:\arno\test\lib\site-packages\telegram\ext\dispatcher.py", line 278, in <genexpr>
    for handler in (x for x in self.handlers[group] if x.check_update(update)):
  File "J:\arno\test\lib\site-packages\telegram\ext\conversationhandler.py", line 264, in check_update
    if entry_point.check_update(update):
  File "J:\arno\test\lib\site-packages\telegram\ext\handler.py", line 85, in check_update
    raise NotImplementedError
NotImplementedError
2018-06-04 20:29:50,026 - ERROR - An uncaught error was raised while processing the update
Traceback (most recent call last):
  File "J:\arno\test\lib\site-packages\telegram\ext\dispatcher.py", line 278, in process_update
    for handler in (x for x in self.handlers[group] if x.check_update(update)):
  File "J:\arno\test\lib\site-packages\telegram\ext\dispatcher.py", line 278, in <genexpr>
    for handler in (x for x in self.handlers[group] if x.check_update(update)):
  File "J:\arno\test\lib\site-packages\telegram\ext\conversationhandler.py", line 264, in check_update
    if entry_point.check_update(update):
  File "J:\arno\test\lib\site-packages\telegram\ext\handler.py", line 85, in check_update
    raise NotImplementedError
NotImplementedError
2018-06-04 20:29:50,026 - ERROR - An uncaught error was raised while processing the update
Traceback (most recent call last):
  File "J:\arno\test\lib\site-packages\telegram\ext\dispatcher.py", line 278, in process_update
    for handler in (x for x in self.handlers[group] if x.check_update(update)):
  File "J:\arno\test\lib\site-packages\telegram\ext\dispatcher.py", line 278, in <genexpr>
    for handler in (x for x in self.handlers[group] if x.check_update(update)):
  File "J:\arno\test\lib\site-packages\telegram\ext\conversationhandler.py", line 264, in check_update
    if entry_point.check_update(update):
  File "J:\arno\test\lib\site-packages\telegram\ext\handler.py", line 85, in check_update
    raise NotImplementedError
NotImplementedError
2018-06-04 20:29:50,026 - ERROR - An uncaught error was raised while processing the update
Traceback (most recent call last):
  File "J:\arno\test\lib\site-packages\telegram\ext\dispatcher.py", line 278, in process_update
    for handler in (x for x in self.handlers[group] if x.check_update(update)):
  File "J:\arno\test\lib\site-packages\telegram\ext\dispatcher.py", line 278, in <genexpr>
    for handler in (x for x in self.handlers[group] if x.check_update(update)):
  File "J:\arno\test\lib\site-packages\telegram\ext\conversationhandler.py", line 264, in check_update
    if entry_point.check_update(update):
  File "J:\arno\test\lib\site-packages\telegram\ext\handler.py", line 85, in check_update
    raise NotImplementedError
NotImplementedError
2018-06-04 20:29:50,026 - ERROR - An uncaught error was raised while processing the update
Traceback (most recent call last):
  File "J:\arno\test\lib\site-packages\telegram\ext\dispatcher.py", line 278, in process_update
    for handler in (x for x in self.handlers[group] if x.check_update(update)):
  File "J:\arno\test\lib\site-packages\telegram\ext\dispatcher.py", line 278, in <genexpr>
    for handler in (x for x in self.handlers[group] if x.check_update(update)):
  File "J:\arno\test\lib\site-packages\telegram\ext\conversationhandler.py", line 264, in check_update
    if entry_point.check_update(update):
  File "J:\arno\test\lib\site-packages\telegram\ext\handler.py", line 85, in check_update
    raise NotImplementedError
NotImplementedError
2018-06-04 20:29:50,026 - ERROR - An uncaught error was raised while processing the update
Traceback (most recent call last):
  File "J:\arno\test\lib\site-packages\telegram\ext\dispatcher.py", line 278, in process_update
    for handler in (x for x in self.handlers[group] if x.check_update(update)):
  File "J:\arno\test\lib\site-packages\telegram\ext\dispatcher.py", line 278, in <genexpr>
    for handler in (x for x in self.handlers[group] if x.check_update(update)):
  File "J:\arno\test\lib\site-packages\telegram\ext\conversationhandler.py", line 264, in check_update
    if entry_point.check_update(update):
  File "J:\arno\test\lib\site-packages\telegram\ext\handler.py", line 85, in check_update
    raise NotImplementedError
NotImplementedError
2018-06-04 20:29:50,028 - ERROR - An uncaught error was raised while processing the update
Traceback (most recent call last):
  File "J:\arno\test\lib\site-packages\telegram\ext\dispatcher.py", line 278, in process_update
    for handler in (x for x in self.handlers[group] if x.check_update(update)):
  File "J:\arno\test\lib\site-packages\telegram\ext\dispatcher.py", line 278, in <genexpr>
    for handler in (x for x in self.handlers[group] if x.check_update(update)):
  File "J:\arno\test\lib\site-packages\telegram\ext\conversationhandler.py", line 264, in check_update
    if entry_point.check_update(update):
  File "J:\arno\test\lib\site-packages\telegram\ext\handler.py", line 85, in check_update
    raise NotImplementedError
NotImplementedError
2018-06-04 20:29:51,769 - WARNING - A TelegramError was raised while processing the Update
2018-06-04 20:29:51,769 - ERROR - No error handlers are registered, logging exception...
Traceback (most recent call last):
  File "J:\arno\test\lib\site-packages\telegram\ext\dispatcher.py", line 279, in process_update
    handler.handle_update(update, self)
  File "J:\arno\test\lib\site-packages\telegram\ext\commandhandler.py", line 173, in handle_update
    return self.callback(dispatcher.bot, update, **optional_args)
  File "telegram_bot.py", line 22, in start
    reply_markup=ReplyKeyboardMarkup(reply_keyboard)
  File "J:\arno\test\lib\site-packages\telegram\message.py", line 432, in reply_text
    return self.bot.send_message(self.chat_id, *args, **kwargs)
  File "J:\arno\test\lib\site-packages\telegram\bot.py", line 60, in decorator
    result = func(self, *args, **kwargs)
  File "J:\arno\test\lib\site-packages\telegram\bot.py", line 85, in decorator
    result = self._request.post(url, data, timeout=kwargs.get('timeout'))
  File "J:\arno\test\lib\site-packages\telegram\utils\request.py", line 278, in post
    **urlopen_kwargs)
  File "J:\arno\test\lib\site-packages\telegram\utils\request.py", line 215, in _request_wrapper
    raise BadRequest(message)
BadRequest: Reply message not found
2018-06-04 20:29:52,000 - WARNING - A TelegramError was raised while processing the Update
2018-06-04 20:29:52,000 - ERROR - No error handlers are registered, logging exception...
Traceback (most recent call last):
  File "J:\arno\test\lib\site-packages\telegram\ext\dispatcher.py", line 279, in process_update
    handler.handle_update(update, self)
  File "J:\arno\test\lib\site-packages\telegram\ext\commandhandler.py", line 173, in handle_update
    return self.callback(dispatcher.bot, update, **optional_args)
  File "telegram_bot.py", line 22, in start
    reply_markup=ReplyKeyboardMarkup(reply_keyboard)
  File "J:\arno\test\lib\site-packages\telegram\message.py", line 432, in reply_text
    return self.bot.send_message(self.chat_id, *args, **kwargs)
  File "J:\arno\test\lib\site-packages\telegram\bot.py", line 60, in decorator
    result = func(self, *args, **kwargs)
  File "J:\arno\test\lib\site-packages\telegram\bot.py", line 85, in decorator
    result = self._request.post(url, data, timeout=kwargs.get('timeout'))
  File "J:\arno\test\lib\site-packages\telegram\utils\request.py", line 278, in post
    **urlopen_kwargs)
  File "J:\arno\test\lib\site-packages\telegram\utils\request.py", line 215, in _request_wrapper
    raise BadRequest(message)
BadRequest: Reply message not found
2018-06-04 20:29:52,612 - ERROR - An uncaught error was raised while processing the update
Traceback (most recent call last):
  File "J:\arno\test\lib\site-packages\telegram\ext\dispatcher.py", line 278, in process_update
    for handler in (x for x in self.handlers[group] if x.check_update(update)):
  File "J:\arno\test\lib\site-packages\telegram\ext\dispatcher.py", line 278, in <genexpr>
    for handler in (x for x in self.handlers[group] if x.check_update(update)):
  File "J:\arno\test\lib\site-packages\telegram\ext\conversationhandler.py", line 264, in check_update
    if entry_point.check_update(update):
  File "J:\arno\test\lib\site-packages\telegram\ext\handler.py", line 85, in check_update
    raise NotImplementedError
NotImplementedError
2018-06-04 20:29:52,612 - ERROR - An uncaught error was raised while processing the update
Traceback (most recent call last):
  File "J:\arno\test\lib\site-packages\telegram\ext\dispatcher.py", line 278, in process_update
    for handler in (x for x in self.handlers[group] if x.check_update(update)):
  File "J:\arno\test\lib\site-packages\telegram\ext\dispatcher.py", line 278, in <genexpr>
    for handler in (x for x in self.handlers[group] if x.check_update(update)):
  File "J:\arno\test\lib\site-packages\telegram\ext\conversationhandler.py", line 264, in check_update
    if entry_point.check_update(update):
  File "J:\arno\test\lib\site-packages\telegram\ext\handler.py", line 85, in check_update
    raise NotImplementedError
NotImplementedError
2018-06-04 20:29:52,612 - ERROR - An uncaught error was raised while processing the update
Traceback (most recent call last):
  File "J:\arno\test\lib\site-packages\telegram\ext\dispatcher.py", line 278, in process_update
    for handler in (x for x in self.handlers[group] if x.check_update(update)):
  File "J:\arno\test\lib\site-packages\telegram\ext\dispatcher.py", line 278, in <genexpr>
    for handler in (x for x in self.handlers[group] if x.check_update(update)):
  File "J:\arno\test\lib\site-packages\telegram\ext\conversationhandler.py", line 264, in check_update
    if entry_point.check_update(update):
  File "J:\arno\test\lib\site-packages\telegram\ext\handler.py", line 85, in check_update
    raise NotImplementedError
NotImplementedError
2018-06-04 20:29:52,614 - ERROR - An uncaught error was raised while processing the update
Traceback (most recent call last):
  File "J:\arno\test\lib\site-packages\telegram\ext\dispatcher.py", line 278, in process_update
    for handler in (x for x in self.handlers[group] if x.check_update(update)):
  File "J:\arno\test\lib\site-packages\telegram\ext\dispatcher.py", line 278, in <genexpr>
    for handler in (x for x in self.handlers[group] if x.check_update(update)):
  File "J:\arno\test\lib\site-packages\telegram\ext\conversationhandler.py", line 264, in check_update
    if entry_point.check_update(update):
  File "J:\arno\test\lib\site-packages\telegram\ext\handler.py", line 85, in check_update
    raise NotImplementedError
NotImplementedError
2018-06-04 20:30:00,075 - ERROR - An uncaught error was raised while processing the update
Traceback (most recent call last):
  File "J:\arno\test\lib\site-packages\telegram\ext\dispatcher.py", line 278, in process_update
    for handler in (x for x in self.handlers[group] if x.check_update(update)):
  File "J:\arno\test\lib\site-packages\telegram\ext\dispatcher.py", line 278, in <genexpr>
    for handler in (x for x in self.handlers[group] if x.check_update(update)):
  File "J:\arno\test\lib\site-packages\telegram\ext\conversationhandler.py", line 264, in check_update
    if entry_point.check_update(update):
  File "J:\arno\test\lib\site-packages\telegram\ext\handler.py", line 85, in check_update
    raise NotImplementedError
NotImplementedError
2018-06-04 20:30:01,296 - ERROR - An uncaught error was raised while processing the update
Traceback (most recent call last):
  File "J:\arno\test\lib\site-packages\telegram\ext\dispatcher.py", line 278, in process_update
    for handler in (x for x in self.handlers[group] if x.check_update(update)):
  File "J:\arno\test\lib\site-packages\telegram\ext\dispatcher.py", line 278, in <genexpr>
    for handler in (x for x in self.handlers[group] if x.check_update(update)):
  File "J:\arno\test\lib\site-packages\telegram\ext\conversationhandler.py", line 264, in check_update
    if entry_point.check_update(update):
  File "J:\arno\test\lib\site-packages\telegram\ext\handler.py", line 85, in check_update
    raise NotImplementedError
NotImplementedError
2018-06-04 20:30:02,364 - ERROR - An uncaught error was raised while processing the update
Traceback (most recent call last):
  File "J:\arno\test\lib\site-packages\telegram\ext\dispatcher.py", line 278, in process_update
    for handler in (x for x in self.handlers[group] if x.check_update(update)):
  File "J:\arno\test\lib\site-packages\telegram\ext\dispatcher.py", line 278, in <genexpr>
    for handler in (x for x in self.handlers[group] if x.check_update(update)):
  File "J:\arno\test\lib\site-packages\telegram\ext\conversationhandler.py", line 264, in check_update
    if entry_point.check_update(update):
  File "J:\arno\test\lib\site-packages\telegram\ext\handler.py", line 85, in check_update
    raise NotImplementedError
NotImplementedError
2018-06-04 20:30:03,190 - ERROR - An uncaught error was raised while processing the update
Traceback (most recent call last):
  File "J:\arno\test\lib\site-packages\telegram\ext\dispatcher.py", line 278, in process_update
    for handler in (x for x in self.handlers[group] if x.check_update(update)):
  File "J:\arno\test\lib\site-packages\telegram\ext\dispatcher.py", line 278, in <genexpr>
    for handler in (x for x in self.handlers[group] if x.check_update(update)):
  File "J:\arno\test\lib\site-packages\telegram\ext\conversationhandler.py", line 264, in check_update
    if entry_point.check_update(update):
  File "J:\arno\test\lib\site-packages\telegram\ext\handler.py", line 85, in check_update
    raise NotImplementedError
NotImplementedError
2018-06-04 20:30:59,625 - INFO - Received signal 2 (SIGINT), stopping...
2018-06-04 20:30:59,811 - WARNING - Exiting immediately!
2018-06-04 20:34:15,305 - INFO - Received signal 2 (SIGINT), stopping...
2018-06-04 20:34:15,480 - WARNING - Exiting immediately!
2018-06-04 20:34:20,661 - ERROR - An uncaught error was raised while processing the update
Traceback (most recent call last):
  File "J:\arno\test\lib\site-packages\telegram\ext\dispatcher.py", line 279, in process_update
    handler.handle_update(update, self)
  File "J:\arno\test\lib\site-packages\telegram\ext\commandhandler.py", line 173, in handle_update
    return self.callback(dispatcher.bot, update, **optional_args)
  File "telegram_bot.py", line 22, in start
    reply_markup=InlineKeyboardButton(reply_keyboard)
  File "J:\arno\test\lib\site-packages\telegram\message.py", line 432, in reply_text
    return self.bot.send_message(self.chat_id, *args, **kwargs)
  File "J:\arno\test\lib\site-packages\telegram\bot.py", line 60, in decorator
    result = func(self, *args, **kwargs)
  File "J:\arno\test\lib\site-packages\telegram\bot.py", line 85, in decorator
    result = self._request.post(url, data, timeout=kwargs.get('timeout'))
  File "J:\arno\test\lib\site-packages\telegram\utils\request.py", line 272, in post
    data = json.dumps(data)
  File "c:\python27\Lib\json\__init__.py", line 244, in dumps
    return _default_encoder.encode(obj)
  File "c:\python27\Lib\json\encoder.py", line 207, in encode
    chunks = self.iterencode(o, _one_shot=True)
  File "c:\python27\Lib\json\encoder.py", line 270, in iterencode
    return _iterencode(o, 0)
  File "c:\python27\Lib\json\encoder.py", line 184, in default
    raise TypeError(repr(o) + " is not JSON serializable")
TypeError: <telegram.inline.inlinekeyboardbutton.InlineKeyboardButton object at 0x05D56B70> is not JSON serializable
2018-06-04 20:36:01,714 - INFO - Received signal 2 (SIGINT), stopping...
2018-06-04 20:36:01,865 - WARNING - Exiting immediately!
2018-06-04 20:36:07,013 - ERROR - An uncaught error was raised while processing the update
Traceback (most recent call last):
  File "J:\arno\test\lib\site-packages\telegram\ext\dispatcher.py", line 279, in process_update
    handler.handle_update(update, self)
  File "J:\arno\test\lib\site-packages\telegram\ext\commandhandler.py", line 173, in handle_update
    return self.callback(dispatcher.bot, update, **optional_args)
  File "telegram_bot.py", line 20, in start
    update.message.reply(
AttributeError: 'Message' object has no attribute 'reply'
2018-06-04 20:36:29,450 - INFO - Received signal 2 (SIGINT), stopping...
2018-06-04 20:36:29,618 - WARNING - Exiting immediately!
2018-06-04 20:36:35,099 - ERROR - An uncaught error was raised while processing the update
Traceback (most recent call last):
  File "J:\arno\test\lib\site-packages\telegram\ext\dispatcher.py", line 279, in process_update
    handler.handle_update(update, self)
  File "J:\arno\test\lib\site-packages\telegram\ext\commandhandler.py", line 173, in handle_update
    return self.callback(dispatcher.bot, update, **optional_args)
  File "telegram_bot.py", line 21, in start
    update.message.reply(
AttributeError: 'Message' object has no attribute 'reply'
2018-06-04 20:37:08,302 - ERROR - An uncaught error was raised while processing the update
Traceback (most recent call last):
  File "J:\arno\test\lib\site-packages\telegram\ext\dispatcher.py", line 279, in process_update
    handler.handle_update(update, self)
  File "J:\arno\test\lib\site-packages\telegram\ext\commandhandler.py", line 173, in handle_update
    return self.callback(dispatcher.bot, update, **optional_args)
  File "telegram_bot.py", line 21, in start
    update.message.reply(
AttributeError: 'Message' object has no attribute 'reply'
2018-06-04 20:37:21,625 - INFO - Received signal 2 (SIGINT), stopping...
2018-06-04 20:37:21,753 - WARNING - Exiting immediately!
2018-06-04 20:37:26,457 - ERROR - An uncaught error was raised while processing the update
Traceback (most recent call last):
  File "J:\arno\test\lib\site-packages\telegram\ext\dispatcher.py", line 279, in process_update
    handler.handle_update(update, self)
  File "J:\arno\test\lib\site-packages\telegram\ext\commandhandler.py", line 173, in handle_update
    return self.callback(dispatcher.bot, update, **optional_args)
  File "telegram_bot.py", line 21, in start
    update.message.reply(
AttributeError: 'Message' object has no attribute 'reply'
2018-06-04 20:38:02,401 - INFO - Received signal 2 (SIGINT), stopping...
2018-06-04 20:38:06,476 - WARNING - Exiting immediately!
2018-06-04 20:38:58,642 - ERROR - An uncaught error was raised while processing the update
Traceback (most recent call last):
  File "J:\arno\test\lib\site-packages\telegram\ext\dispatcher.py", line 279, in process_update
    handler.handle_update(update, self)
  File "J:\arno\test\lib\site-packages\telegram\ext\commandhandler.py", line 173, in handle_update
    return self.callback(dispatcher.bot, update, **optional_args)
  File "telegram_bot.py", line 22, in start
    reply_markup=ReplyKeyboardMarkup(reply_keyboard)
  File "J:\arno\test\lib\site-packages\telegram\message.py", line 453, in reply_markdown
    return self.bot.send_message(self.chat_id, *args, **kwargs)
  File "J:\arno\test\lib\site-packages\telegram\bot.py", line 60, in decorator
    result = func(self, *args, **kwargs)
  File "J:\arno\test\lib\site-packages\telegram\bot.py", line 71, in decorator
    url, data = func(self, *args, **kwargs)
TypeError: send_message() takes at least 3 arguments (4 given)
2018-06-04 20:39:22,450 - INFO - Received signal 2 (SIGINT), stopping...
2018-06-04 20:39:22,585 - WARNING - Exiting immediately!
2018-06-04 20:40:24,934 - ERROR - An uncaught error was raised while processing the update
Traceback (most recent call last):
  File "J:\arno\test\lib\site-packages\telegram\ext\dispatcher.py", line 279, in process_update
    handler.handle_update(update, self)
  File "J:\arno\test\lib\site-packages\telegram\ext\commandhandler.py", line 173, in handle_update
    return self.callback(dispatcher.bot, update, **optional_args)
  File "telegram_bot.py", line 22, in start
    reply_markup=ReplyKeyboardMarkup(reply_keyboard)
  File "J:\arno\test\lib\site-packages\telegram\message.py", line 453, in reply_markdown
    return self.bot.send_message(self.chat_id, *args, **kwargs)
  File "J:\arno\test\lib\site-packages\telegram\bot.py", line 60, in decorator
    result = func(self, *args, **kwargs)
  File "J:\arno\test\lib\site-packages\telegram\bot.py", line 71, in decorator
    url, data = func(self, *args, **kwargs)
TypeError: send_message() takes at least 3 arguments (4 given)
2018-06-04 20:40:55,753 - INFO - Received signal 2 (SIGINT), stopping...
2018-06-04 20:40:55,881 - WARNING - Exiting immediately!
2018-06-04 20:41:11,997 - ERROR - An uncaught error was raised while processing the update
Traceback (most recent call last):
  File "J:\arno\test\lib\site-packages\telegram\ext\dispatcher.py", line 279, in process_update
    handler.handle_update(update, self)
  File "J:\arno\test\lib\site-packages\telegram\ext\commandhandler.py", line 173, in handle_update
    return self.callback(dispatcher.bot, update, **optional_args)
  File "telegram_bot.py", line 22, in start
    ReplyKeyboardMarkup(reply_keyboard)
  File "J:\arno\test\lib\site-packages\telegram\message.py", line 453, in reply_markdown
    return self.bot.send_message(self.chat_id, *args, **kwargs)
  File "J:\arno\test\lib\site-packages\telegram\bot.py", line 60, in decorator
    result = func(self, *args, **kwargs)
  File "J:\arno\test\lib\site-packages\telegram\bot.py", line 85, in decorator
    result = self._request.post(url, data, timeout=kwargs.get('timeout'))
  File "J:\arno\test\lib\site-packages\telegram\utils\request.py", line 272, in post
    data = json.dumps(data)
  File "c:\python27\Lib\json\__init__.py", line 244, in dumps
    return _default_encoder.encode(obj)
  File "c:\python27\Lib\json\encoder.py", line 207, in encode
    chunks = self.iterencode(o, _one_shot=True)
  File "c:\python27\Lib\json\encoder.py", line 270, in iterencode
    return _iterencode(o, 0)
  File "c:\python27\Lib\json\encoder.py", line 184, in default
    raise TypeError(repr(o) + " is not JSON serializable")
TypeError: <telegram.replykeyboardmarkup.ReplyKeyboardMarkup object at 0x060D6AF0> is not JSON serializable
2018-06-04 20:41:28,960 - INFO - Received signal 2 (SIGINT), stopping...
2018-06-04 20:41:32,463 - WARNING - Exiting immediately!
2018-06-04 20:47:14,792 - ERROR - An uncaught error was raised while processing the update
Traceback (most recent call last):
  File "J:\arno\test\lib\site-packages\telegram\ext\dispatcher.py", line 279, in process_update
    handler.handle_update(update, self)
  File "J:\arno\test\lib\site-packages\telegram\ext\commandhandler.py", line 173, in handle_update
    return self.callback(dispatcher.bot, update, **optional_args)
  File "telegram_bot.py", line 22, in start
    reply_markup=ReplyKeyboardMarkup(reply_keyboard)
  File "J:\arno\test\lib\site-packages\telegram\message.py", line 432, in reply_text
    return self.bot.send_message(self.chat_id, *args, **kwargs)
  File "J:\arno\test\lib\site-packages\telegram\bot.py", line 60, in decorator
    result = func(self, *args, **kwargs)
  File "J:\arno\test\lib\site-packages\telegram\bot.py", line 71, in decorator
    url, data = func(self, *args, **kwargs)
TypeError: send_message() takes at least 3 arguments (3 given)
2018-06-04 20:47:41,858 - INFO - Received signal 2 (SIGINT), stopping...
2018-06-04 20:47:42,032 - WARNING - Exiting immediately!
2018-06-04 20:47:47,144 - ERROR - An uncaught error was raised while processing the update
Traceback (most recent call last):
  File "J:\arno\test\lib\site-packages\telegram\ext\dispatcher.py", line 279, in process_update
    handler.handle_update(update, self)
  File "J:\arno\test\lib\site-packages\telegram\ext\commandhandler.py", line 173, in handle_update
    return self.callback(dispatcher.bot, update, **optional_args)
  File "telegram_bot.py", line 22, in start
    reply_markup=ReplyKeyboardMarkup(reply_keyboard)
  File "J:\arno\test\lib\site-packages\telegram\message.py", line 432, in reply_text
    return self.bot.send_message(self.chat_id, *args, **kwargs)
  File "J:\arno\test\lib\site-packages\telegram\bot.py", line 60, in decorator
    result = func(self, *args, **kwargs)
  File "J:\arno\test\lib\site-packages\telegram\bot.py", line 71, in decorator
    url, data = func(self, *args, **kwargs)
TypeError: send_message() takes at least 3 arguments (3 given)
2018-06-04 20:49:23,586 - INFO - Received signal 2 (SIGINT), stopping...
2018-06-04 20:49:23,744 - WARNING - Exiting immediately!
2018-06-04 20:49:33,746 - WARNING - A TelegramError was raised while processing the Update
2018-06-04 20:49:33,746 - ERROR - No error handlers are registered, logging exception...
Traceback (most recent call last):
  File "J:\arno\test\lib\site-packages\telegram\ext\dispatcher.py", line 279, in process_update
    handler.handle_update(update, self)
  File "J:\arno\test\lib\site-packages\telegram\ext\commandhandler.py", line 173, in handle_update
    return self.callback(dispatcher.bot, update, **optional_args)
  File "telegram_bot.py", line 22, in start
    reply_markup=ReplyKeyboardMarkup(reply_keyboard)
  File "J:\arno\test\lib\site-packages\telegram\message.py", line 432, in reply_text
    return self.bot.send_message(self.chat_id, *args, **kwargs)
  File "J:\arno\test\lib\site-packages\telegram\bot.py", line 60, in decorator
    result = func(self, *args, **kwargs)
  File "J:\arno\test\lib\site-packages\telegram\bot.py", line 85, in decorator
    result = self._request.post(url, data, timeout=kwargs.get('timeout'))
  File "J:\arno\test\lib\site-packages\telegram\utils\request.py", line 278, in post
    **urlopen_kwargs)
  File "J:\arno\test\lib\site-packages\telegram\utils\request.py", line 215, in _request_wrapper
    raise BadRequest(message)
BadRequest: Message must be non-empty
2018-06-04 20:50:34,082 - INFO - Received signal 2 (SIGINT), stopping...
2018-06-04 20:50:34,242 - WARNING - Exiting immediately!
2018-06-04 20:51:43,306 - INFO - Received signal 2 (SIGINT), stopping...
2018-06-04 20:51:43,443 - WARNING - Exiting immediately!
2018-06-04 21:38:05,460 - ERROR - An uncaught error was raised while processing the update
Traceback (most recent call last):
  File "J:\arno\test\lib\site-packages\telegram\ext\dispatcher.py", line 279, in process_update
    handler.handle_update(update, self)
  File "J:\arno\test\lib\site-packages\telegram\ext\commandhandler.py", line 173, in handle_update
    return self.callback(dispatcher.bot, update, **optional_args)
TypeError: at() takes exactly 3 arguments (2 given)
2018-06-04 21:38:05,461 - ERROR - An uncaught error was raised while processing the update
Traceback (most recent call last):
  File "J:\arno\test\lib\site-packages\telegram\ext\dispatcher.py", line 279, in process_update
    handler.handle_update(update, self)
  File "J:\arno\test\lib\site-packages\telegram\ext\commandhandler.py", line 173, in handle_update
    return self.callback(dispatcher.bot, update, **optional_args)
TypeError: at() takes exactly 3 arguments (2 given)
2018-06-04 21:38:05,630 - ERROR - An uncaught error was raised while processing the update
Traceback (most recent call last):
  File "J:\arno\test\lib\site-packages\telegram\ext\dispatcher.py", line 279, in process_update
    handler.handle_update(update, self)
  File "J:\arno\test\lib\site-packages\telegram\ext\commandhandler.py", line 173, in handle_update
    return self.callback(dispatcher.bot, update, **optional_args)
TypeError: at() takes exactly 3 arguments (2 given)
2018-06-04 21:39:02,473 - INFO - Received signal 2 (SIGINT), stopping...
2018-06-04 21:39:02,619 - WARNING - Exiting immediately!
2018-06-04 21:39:54,917 - ERROR - An uncaught error was raised while processing the update
Traceback (most recent call last):
  File "J:\arno\test\lib\site-packages\telegram\ext\dispatcher.py", line 279, in process_update
    handler.handle_update(update, self)
  File "J:\arno\test\lib\site-packages\telegram\ext\commandhandler.py", line 173, in handle_update
    return self.callback(dispatcher.bot, update, **optional_args)
  File "telegram_bot.py", line 47, in at
    if args[0].lower() == 'all':
IndexError: list index out of range
2018-06-04 21:40:54,548 - ERROR - An uncaught error was raised while processing the update
Traceback (most recent call last):
  File "J:\arno\test\lib\site-packages\telegram\ext\dispatcher.py", line 279, in process_update
    handler.handle_update(update, self)
  File "J:\arno\test\lib\site-packages\telegram\ext\commandhandler.py", line 173, in handle_update
    return self.callback(dispatcher.bot, update, **optional_args)
  File "telegram_bot.py", line 47, in at
    
IndexError: list index out of range
2018-06-04 21:41:20,818 - INFO - Received signal 2 (SIGINT), stopping...
2018-06-04 21:41:20,970 - WARNING - Exiting immediately!
2018-06-04 21:41:26,503 - ERROR - An uncaught error was raised while processing the update
Traceback (most recent call last):
  File "J:\arno\test\lib\site-packages\telegram\ext\dispatcher.py", line 279, in process_update
    handler.handle_update(update, self)
  File "J:\arno\test\lib\site-packages\telegram\ext\commandhandler.py", line 173, in handle_update
    return self.callback(dispatcher.bot, update, **optional_args)
  File "telegram_bot.py", line 36, in at
    if args[0].lower() == 'all':
IndexError: list index out of range
2018-06-04 21:41:38,753 - INFO - Received signal 2 (SIGINT), stopping...
2018-06-04 21:41:38,914 - WARNING - Exiting immediately!
2018-06-04 21:41:48,128 - ERROR - An uncaught error was raised while processing the update
Traceback (most recent call last):
  File "J:\arno\test\lib\site-packages\telegram\ext\dispatcher.py", line 279, in process_update
    handler.handle_update(update, self)
  File "J:\arno\test\lib\site-packages\telegram\ext\commandhandler.py", line 173, in handle_update
    return self.callback(dispatcher.bot, update, **optional_args)
  File "telegram_bot.py", line 36, in at
    if args[0].lower() == 'all':
IndexError: list index out of range
2018-06-04 21:44:19,042 - INFO - Received signal 2 (SIGINT), stopping...
2018-06-04 21:44:19,177 - WARNING - Exiting immediately!
2018-06-04 21:45:39,410 - INFO - Received signal 2 (SIGINT), stopping...
2018-06-04 21:45:39,553 - WARNING - Exiting immediately!
2018-06-04 21:45:45,894 - ERROR - An uncaught error was raised while processing the update
Traceback (most recent call last):
  File "J:\arno\test\lib\site-packages\telegram\ext\dispatcher.py", line 279, in process_update
    handler.handle_update(update, self)
  File "J:\arno\test\lib\site-packages\telegram\ext\commandhandler.py", line 173, in handle_update
    return self.callback(dispatcher.bot, update, **optional_args)
  File "telegram_bot.py", line 36, in at
    if args[0].lower() == 'all':
IndexError: list index out of range
2018-06-04 21:47:16,665 - INFO - Received signal 2 (SIGINT), stopping...
2018-06-04 21:47:16,809 - WARNING - Exiting immediately!
2018-06-04 21:47:24,201 - ERROR - An uncaught error was raised while processing the update
Traceback (most recent call last):
  File "J:\arno\test\lib\site-packages\telegram\ext\dispatcher.py", line 279, in process_update
    handler.handle_update(update, self)
  File "J:\arno\test\lib\site-packages\telegram\ext\commandhandler.py", line 173, in handle_update
    return self.callback(dispatcher.bot, update, **optional_args)
  File "telegram_bot.py", line 37, in at
    if args[0].lower() == 'all':
IndexError: list index out of range
2018-06-04 21:47:46,980 - INFO - Received signal 2 (SIGINT), stopping...
2018-06-04 21:47:47,114 - WARNING - Exiting immediately!
2018-06-04 21:48:28,403 - INFO - Received signal 2 (SIGINT), stopping...
2018-06-04 21:48:28,569 - WARNING - Exiting immediately!
2018-06-04 21:49:04,588 - INFO - Received signal 2 (SIGINT), stopping...
2018-06-04 21:49:04,744 - WARNING - Exiting immediately!
2018-06-04 21:50:00,349 - ERROR - An uncaught error was raised while processing the update
Traceback (most recent call last):
  File "J:\arno\test\lib\site-packages\telegram\ext\dispatcher.py", line 279, in process_update
    handler.handle_update(update, self)
  File "J:\arno\test\lib\site-packages\telegram\ext\commandhandler.py", line 173, in handle_update
    return self.callback(dispatcher.bot, update, **optional_args)
  File "telegram_bot.py", line 37, in at
    if args[0].lower() == 'all':
IndexError: list index out of range
2018-06-04 21:50:20,572 - ERROR - An uncaught error was raised while processing the update
Traceback (most recent call last):
  File "J:\arno\test\lib\site-packages\telegram\ext\dispatcher.py", line 279, in process_update
    handler.handle_update(update, self)
  File "J:\arno\test\lib\site-packages\telegram\ext\commandhandler.py", line 173, in handle_update
    return self.callback(dispatcher.bot, update, **optional_args)
  File "telegram_bot.py", line 37, in at
    if args[0].lower() == 'all':
IndexError: list index out of range
2018-06-04 21:52:58,098 - INFO - Received signal 2 (SIGINT), stopping...
2018-06-04 21:52:58,273 - WARNING - Exiting immediately!
2018-06-04 21:55:23,306 - INFO - Received signal 2 (SIGINT), stopping...
2018-06-04 21:55:23,569 - WARNING - Exiting immediately!
2018-06-04 21:57:07,253 - ERROR - An uncaught error was raised while processing the update
Traceback (most recent call last):
  File "J:\arno\test\lib\site-packages\telegram\ext\dispatcher.py", line 279, in process_update
    handler.handle_update(update, self)
  File "J:\arno\test\lib\site-packages\telegram\ext\commandhandler.py", line 173, in handle_update
    return self.callback(dispatcher.bot, update, **optional_args)
  File "telegram_bot.py", line 36, in at
    if settings.TELEGRAM_API['user_group'].has_key(args[0]):
IndexError: list index out of range
2018-06-04 21:58:55,834 - INFO - Received signal 2 (SIGINT), stopping...
2018-06-04 21:58:56,002 - WARNING - Exiting immediately!
